Workbook
Name Engagement_evaluation_status: #REF!

Sheet 교육대상자
A1: 구분 | B1: Eng Code | C1: Eng Name | D1: Name | E1: Email | F1: 구분
A2: 리뷰어 | B2: 1661228 | C2: FY2025_비씨월드제약_외부(지정)감사 | D2: 김소희 | E2: skim66@kr.kpmg.com | F2: 추가 | H2: 2/10 송부
A3: 리뷰어 | B3: 1661228 | C3: FY2025_비씨월드제약_외부(지정)감사 | D3: 이민규 | E3: mingyulee@kr.kpmg.com | F3: 제거 | G3: < 퇴사 | H3: 2/10 송부
A4: 실무자 | B4: 1689529 | C4: [케이씨씨건설] FY2025 외부감사 | D4: 강신형 | E4: shinhyungkang@kr.kpmg.com | F4: 추가 | H4: 2/10 송부
A5: 실무자 | B5: 1685841 | C5: 메가스터디교육_FY2025 외부감사 | D5: 육형문 | E5: hyuk1@kr.kpmg.com | F5: 추가 | H5: 2/19 송부
A6: 실무자 | B6: 1685841 | C6: 메가스터디교육_FY2025 외부감사 | D6: 한청원 | E6: cheongwonhan@kr.kpmg.com | F6: 추가 | H6: 2/19 송부
A7: 실무자 | B7: 1669115 | C7: 현대백화점 2025년 외부감사 | D7: 박정주 | E7: jungjoopark@kr.kpmg.com | F7: 추가 | H7: 2/19 송부
A8: 실무자 | B8: 1666520 | C8: 2025년 카카오 외부감사 | D8: 오청민 | E8: chungminoh@kr.kpmg.com | F8: 추가 | H8: 2/19 송부
A9: 실무자 | B9: 1666520 | C9: 2025년 카카오 외부감사 | D9: 권혜빈 | E9: hyebinkwon@kr.kpmg.com | F9: 추가 | H9: 2/19 송부
A10: 실무자 | B10: 1684195 | C10: 드림어스컴퍼니_FY2025_외부감사 | D10: 정지은 | E10: jjung30@kr.kpmg.com | F10: 추가 | H10: 2/19 송부
A11: 실무자 | B11: 1657536 | C11: 한일홀딩스 2025년 지정감사(주기적) | D11: 김영준 | E11: ykim186@kr.kpmg.com | F11: 추가 | H11: 2/23 송부
A12: 실무자 | B12: 1682797 | C12: 비와이엔블랙야크 FY25 회계감사 | D12: 한창수 | E12: changsuhan@kr.kpmg.com | F12: 추가 | H12: 2/25 송부
A13: 리뷰어 | B13: 1684738 | C13: FY25 디와이덕양(구, 덕양산업) 외부감사 | D13: 최준성 | E13: jchoi13@kr.kpmg.com | F13: 추가 | H13: 3/3 송부
A14: 실무자 | B14: 1684738 | C14: FY25 디와이덕양(구, 덕양산업) 외부감사 | D14: 정서정 | E14: seojungjung@kr.kpmg.com | F14: 추가 | H14: 3/3 송부
A15: 실무자 | B15: 1684738 | C15: FY25 디와이덕양(구, 덕양산업) 외부감사 | D15: 정현욱 | E15: hyunwookjeong@kr.kpmg.com | F15: 추가 | H15: 3/3 송부
... A22: 실무자 | B22: 1656724 | C22: FY25_아스플로_지정감사 | D22: 김학송 | E22: haksongkim@kr.kpmg.com | F22: 추가 | H22: 3/4 송부

Sheet 보고자료
B2: 1. 현황 요약
B3: 항목 | C3: Eng 현황 | E3: 비고 | J3: #N/A | K3: 0 | L3: 미회신 - STS미신청
B4: 최초 Scoping | D4: 223 | F4: 223 | J4: 1. 서비스 요청 | K4: {=SUMPRODUCT( --IFERROR( ( (COUNTIF($P$4:$P$6, FY25_현황!$AF$8:$AF$998)>0) + (FY25_현황!$AF$8:$AF$998="") )>0,0), --IFERROR(FY25_현황!$DA$8:$DA$998=J4,0) )} -> 0 | L4: 미회신 - 데이터 미업로드
B5: (+) 추가신청 | D5: =FY25_현황!D4-FY25_현황!C4 -> 10 | F5: 9 | J5: 2-1. 데이터 재요청 | K5: {=SUMPRODUCT( --IFERROR( ( (COUNTIF($P$4:$P$6, FY25_현황!$AF$8:$AF$998)>0) + (FY25_현황!$AF$8:$AF$998="") )>0,0), --IFERROR(FY25_현황!$DA$8:$DA$998=J5,0) )} -> 0 | L5: interim 진행중 | P5: 사용
B6: (-) 제외 | D6: =C8+C7 -> -123 | J6: 2. 데이터 업로드 완료 | K6: {=SUMPRODUCT( --IFERROR( ( (COUNTIF($P$4:$P$6, FY25_현황!$AF$8:$AF$998)>0) + (FY25_현황!$AF$8:$AF$998="") )>0,0), --IFERROR(FY25_현황!$DA$8:$DA$998=J6,0) )} -> 0 | L6: interim 진행중
B7: (-) 확인중 | C7: =-(COUNTIF(FY25_현황!AF:AF,"확인중")+COUNTIF(FY25_현황!AF:AF,"통화안됨")) -> 0 | E7: (*) 통화안됨, 확인중 포함 | J7: 3-0. 담당자 지정 완료 | K7: {=SUMPRODUCT( --IFERROR( ( (COUNTIF($P$4:$P$6, FY25_현황!$AF$8:$AF$998)>0) + (FY25_현황!$AF$8:$AF$998="") )>0,0), --IFERROR(FY25_현황!$DA$8:$DA$998=J7,0) )} -> 0 | L7: interim 진행중
B8: (-) 사용 불가 신청 | C8: =-COUNTIF(FY25_현황!AF:AF,"제외요청") -> -123 | J8: 3-3. 앱 프로세싱 중 | K8: {=SUMPRODUCT( --IFERROR( ( (COUNTIF($P$4:$P$6, FY25_현황!$AF$8:$AF$998)>0) + (FY25_현황!$AF$8:$AF$998="") )>0,0), --IFERROR(FY25_현황!$DA$8:$DA$998=J8,0) )} -> 0 | L8: interim 진행중
B9: 현재 Scoping | D9: =SUM(D4:D6) -> 110 | J9: 4. 전처리 오류 처리 중 | K9: {=SUMPRODUCT( --IFERROR( ( (COUNTIF($P$4:$P$6, FY25_현황!$AF$8:$AF$998)>0) + (FY25_현황!$AF$8:$AF$998="") )>0,0), --IFERROR(FY25_현황!$DA$8:$DA$998=J9,0) )} -> 1 | L9: interim 진행중
B10: Interim 완료 | C10: =K10 -> 109 | J10: 5. 작업 완료 | K10: {=SUMPRODUCT( --IFERROR( ( (COUNTIF($P$4:$P$6, FY25_현황!$AF$8:$AF$998)>0) + (FY25_현황!$AF$8:$AF$998="") )>0,0), --IFERROR(FY25_현황!$DA$8:$DA$998=J10,0) )} -> 109 | L10: interim 완료
B11: Interim 진행중 | C11: =D9-C10 -> 1 | E11: (*) 사용예정 포함 | J11: 9. 서비스 취소 | K11: {=SUMPRODUCT( --IFERROR( ( (COUNTIF($P$4:$P$6, FY25_현황!$AF$8:$AF$998)>0) + (FY25_현황!$AF$8:$AF$998="") )>0,0), --IFERROR(FY25_현황!$DA$8:$DA$998=J11,0) )} -> 0 | L11: 미회신 - STS미신청
F12: =D9=(C10+C11) -> TRUE | J12: 합계 | K12: =SUM(K3:K11) -> 110
J13: 3-0. 담당자 지정 완료
B14: Total Feel | C14: Fee/Eng | D14: Eng
B15: 199500
C16: =B15/D16 -> 1830.2752 | D16: 109
C17: =B15/D17 -> 1813.6364 | D17: =D9 -> 110
B21: 항목 | C21: Eng 현황 | E21: 비고
B22: 미확인 | D22: 35
B23: 제외 | C23: 20
B24: 확인중 | C24: 10
B25: 통화안됨 | C25: 1
B26: 사용예정 | C26: 4

Sheet FY25>>>

Sheet FY25_현황
D3: =C4+AF3+AF4 -> 100 | AF3: =COUNTIF(AF8:AF395,"추가신청") -> 0 | AL3: =COUNTIF(AL8:AL1048576,"V") -> 145
C4: =COUNTA(C8:C395) -> 223 | D4: =COUNTA(D8:D395) -> 233 | AF4: =-(COUNTIF(AF8:AF395,"제외요청")+COUNTIF(AF8:AF395,"제외")) -> -123 | AK4: 계(제외요청/제외 빼고) | AL4: =SUBTOTAL(103,AL8:AL236) -> 201 | AM4: =COUNTIF(AM8:AM297,"V")-COUNTIFS(AM8:AM297,"V",$AF$8:$AF$297,"제외요청") -> 102 | AN4: =COUNTIF(AN8:AN297,"V")-COUNTIFS(AN8:AN297,"V",$AF$8:$AF$297,"제외요청") -> 99 | AO4: =COUNTIF(AO8:AO297,"V")-COUNTIFS(AO8:AO297,"V",$AF$8:$AF$297,"제외요청") -> 99 | AP4: =COUNTIF(AP8:AP297,"V")-COUNTIFS(AP8:AP297,"V",$AF$8:$AF$297,"제외요청") -> 99 | AQ4: =SUBTOTAL(103,AQ8:AQ236) -> 104 | AR4: =SUBTOTAL(103,AR8:AR236) -> 104 | AS4: =SUBTOTAL(103,AS8:AS236) -> 56 | AT4: =COUNTIF(AT8:AT297,"V")-COUNTIFS(AT8:AT297,"V",$AF$8:$AF$297,"제외요청") -> 2 | AU4: =COUNTIF(AU8:AU297,"V")-COUNTIFS(AU8:AU297,"V",$AF$8:$AF$297,"제외요청") -> 2 | AW4: =COUNTIF(AW8:AW297,"V")-COUNTIFS(AW8:AW297,"V",$AF$8:$AF$297,"제외요청") -> 78 | AX4: =COUNTIF(AX8:AX297,"V")-COUNTIFS(AX8:AX297,"V",$AF$8:$AF$297,"제외요청") -> 78 | AY4: =COUNTIF(AY8:AY297,"V")-COUNTIFS(AY8:AY297,"V",$AF$8:$AF$297,"제외요청") -> 78 | AZ4: =COUNTIF(AZ8:AZ297,"V")-COUNTIFS(AZ8:AZ297,"V",$AF$8:$AF$297,"제외요청") -> 78 | DC4: {=SUMPRODUCT(--(TRIM(SUBSTITUTE(FY25_현황!DC8:DC998,CHAR(160),""))="V"))} -> 35 | DD4: {=SUMPRODUCT(--(TRIM(SUBSTITUTE(FY25_현황!DD8:DD998,CHAR(160),""))="V"))} -> 123 | DF4: {=SUMPRODUCT(--(TRIM(SUBSTITUTE(FY25_현황!DF8:DF998,CHAR(160),""))="V"))} -> 109
C5: Eng 정보 | D5: Eng 정보 | P5: AITS Setting | AD5: Scoping | AH5: Interim | AV5: Year-end | AW5: Year-end | BA5: 연락처 | DA5: "5. 작업완료"제외하고 붙여넣기
AW6: 감사팀 | AY6: ITA | AZ6: AI | CZ6: 상태값 | DA6: 46056.521
B7: 대기/맵핑/분석/완료 | C7: 최초선정 | D7: NO | E7: 본부명 | F7: 고객코드 | G7: 회사명 | H7: 계약코드 | I7: 계약명 | J7: 법인구분 | K7: KCw | L7: 업종-대분류 | M7: KCw Industry | N7: ERP | O7: 최대 JE Line | P7: Revenue RMM | Q7: Revenue 통제의존 | R7: COGS RMM | S7: COGS 통제의존 | T7: Opex RMM | U7: Opex 통제의존 | V7: Interest income RMM | W7: Interest income 통제의존 | X7: Interest expense RMM | Y7: Interest expense 통제의존 | Z7: Subledger Revenue | AA7: Subledger Opex | AB7: Library | AC7: Industry | AD7: 전년도 참여 | AE7: 변동날짜 | AF7: 변동사항 | AG7: 변동사유 | AH7: 1분기 | AI7: 2분기 | AJ7: 3분기 | AK7: 4분기 | AL7: STS신청 | AM7: Eng 생성 | AN7: Data Upload완료 | AO7: Mapping 완료 | AP7: 감사팀 안내메일(mapping) 발송 | AQ7: 분석 완료 | AR7: AITS 감사팀 전달 | AS7: CAAT조서 작성 | AT7: 추가작업 필요 | AU7: 추가작업 완료 | AV7: 미사용 | AW7: STS Ticket 생성 | AX7: 데이터업로드 | AY7: 전처리/업로드 | AZ7: 분석 결과 제공 | BA7: DPP | BB7: DPP | BC7: DPP | BD7: DPP | BE7: DPP - IT | BF7: DPP - IT | BG7: DPP - Partner | BH7: DPP - Partner | BI7: EQCR | BJ7: EQCR | BK7: EP | BL7: EP | BM7: EP | BN7: EP | BO7: EP | BP7: EP | BQ7: EP | BR7: EP | BS7: EP | BT7: EP | BU7: EM | BV7: EM | BW7: EM | BX7: EM | BY7: EM | BZ7: EM | CA7: EM | CB7: EM | CC7: EM | CD7: EM | CE7: EM | CF7: EM | CG7: ICA | CH7: ICA | CI7: ICA | CJ7: ICA | CK7: Staff | CL7: Staff | CM7: Staff | CN7: Staff | CO7: Staff | CP7: Staff | CQ7: Staff | CR7: Staff | CS7: Staff | CT7: Staff | CU7: Staff | CV7: Staff | CW7: s | CX7: s | CY7: s | CZ7: Eng | DA7: 진행상황 | DC7: 미회신35건 관리 | DD7: 제외 | DF7: 비용청구
C8: 1668793 | D8: 1 | E8: ICE1 | F8: 1000316445 | G8: 에스케이하이닉스 | H8: 1668793 | I8: SK하이닉스 FY2025 외부감사 | J8: 유가증권 | K8: Enhanced | L8: 제조업 | M8: Industrial Products | N8: SAP S4 HANA | O8: 6821774 | P8: 115.2.02 115.2.12b 115.2.13 115.3.01 | Q8: O | R8: N/A | S8: N/A | T8: N/A | U8: N/A | V8: N/A | W8: N/A | X8: N/A | Y8: N/A | Z8: N/A | AA8: N/A | AB8: KR_KPMG Dashboards - IFRS v3.1 - Base Industry: UpdateMay2025 | AC8: Manufacturing | AD8: Y | AH8: V | AI8: V | AJ8: V | AK8: V | AL8: V | AM8: V | AN8: V | AO8: V | AP8: V | AQ8: V | AR8: V | AS8: V | AW8: V | AX8: V | AY8: V | AZ8: V | BA8: 이현경 | BB8: hyunkyunglee@kr.kpmg.com | BE8: 이현강 | BF8: hyeonganglee@kr.kpmg.com | BG8: 이승훈 | BH8: seunghoonlee@kr.kpmg.com | BI8: 변재준 | BJ8: jbyun@kr.kpmg.com | BK8: 윤주헌 | BL8: joohunyoon@kr.kpmg.com | BU8: 김병민 | BV8: byungminkim@kr.kpmg.com | BW8: 송성화 | BX8: sunghwasong@kr.kpmg.com | CG8: 김성훈 | CH8: skim130@kr.kpmg.com | CK8: 이하린 | CL8: harinlee@kr.kpmg.com | CM8: 이가은 | CN8: glee34@kr.kpmg.com | CY8: s | CZ8: SK하이닉스 FY2025 외부감사 | DA8: 5. 작업 완료 | DD8: =IF(AF8="제외요청", "V","") | DF8: V
A9: 박정빈 | B9: 완료 | C9: 1698103 | D9: 2 | E9: IM4 | F9: 1000317342 | G9: Korea Electric Power Corporation | H9: 1698103 | I9: FY25_한국전력공사_외부회계감사 | J9: 유가증권(FPI) | K9: Enhanced | L9: 전력사업 | M9: Energy and Natural Resources | N9: SAP S4 ECC | O9: 240745021 | P9: N/A | Q9: N/A | R9: N/A | S9: N/A | T9: 100.2.02 | U9: O | V9: N/A | W9: N/A | X9: N/A | Y9: N/A | Z9: N/A | AA9: N/A | AB9: KR_KPMG Dashboards - IFRS v3.1 - Base Industry: UpdateMay2025 | AC9: Utilities | AD9: N | AH9: V | AL9: V | AM9: V | AN9: V | AO9: V | AP9: V | AQ9: V | AR9: V | AT9: V | AU9: V | AW9: V | AX9: V | AY9: V | AZ9: V | BA9: 김수연 | BB9: sooyeonkim@kr.kpmg.com | BE9: 서은아 | BF9: eseo@kr.kpmg.com | BG9: Cao, Leah | BH9: leahcao@kr.kpmg.com | BI9: 황재남 | BJ9: jaenamhwang@kr.kpmg.com | BK9: 이정수 | BL9: jungsoolee@kr.kpmg.com | BU9: 전태웅 | BV9: taeungjeon@kr.kpmg.com | CG9: 정재정 | CH9: jaejeongjeong@kr.kpmg.com | CK9: 김상훈 | CL9: skim191@kr.kpmg.com | CM9: 최서영 | CN9: seoyoungchoi@kr.kpmg.com | CZ9: FY25_한국전력공사_외부회계감사 | DA9: 5. 작업 완료 | DD9: =IF(AF9="제외요청", "V","") | DF9: V
C10: 1698595 | D10: 3 | E10: IM4 | F10: 1000314674 | G10: 한국수력원자력 ㈜ | H10: 1698595 | I10: [한국수력원자력] FY2025 회계감사 | J10: 유가증권 | K10: Enhanced | M10: 에너지 및 천연자원 사업 | N10: SAP S4 HANA | O10: 1701147 | P10: 115.2.02 115.2.13 115.2.02 115.2.12b | Q10: O | R10: N/A | S10: N/A | T10: 100.2.02 | U10: O | V10: N/A | W10: N/A | X10: N/A | Y10: N/A | Z10: N/A | AA10: N/A | AB10: KR_KPMG Dashboards - IFRS v3.1 - Base Industry: UpdateMay2025 | AC10: Utilities | AD10: N | AE10: 46036 | AF10: 제외요청 | AG10: 전수검토 수행 | AH10: V | AL10: V | AM10: V | AN10: V | AO10: V | AP10: V | AQ10: V | AR10: V | AT10: V | AU10: V | BA10: 김수연 | BB10: sooyeonkim@kr.kpmg.com | BE10: 이현강 | BF10: hyeonganglee@kr.kpmg.com | BG10: Cao, Leah | BH10: leahcao@kr.kpmg.com | BI10: 황재남 | BJ10: jaenamhwang@kr.kpmg.com | BK10: 김연정 | BL10: yeonjungkim@kr.kpmg.com | BU10: 김성욱 | BV10: sunguckkim@kr.kpmg.com | CG10: 윤광현 | CH10: kwanghyunyun@kr.kpmg.com | CI10: 이준학 | CJ10: jlee214@kr.kpmg.com | CK10: 김상식 | CL10: sangseekkim@kr.kpmg.com | CM10: 김혜수 | CN10: hyesukim@kr.kpmg.com | CZ10: [한국수력원자력] FY2025 회계감사 | DA10: 5. 작업 완료 | DD10: =IF(AF10="제외요청", "V","") -> V
C11: 1683891 | D11: 4 | E11: ICE3 | F11: 1000315445 | G11: 에스케이브로드밴드 주식회사 | H11: 1683891 | I11: SK브로드밴드 2025년 외부감사 | J11: 일반(채권상장/FPI) | K11: Enhanced | L11: 유선통신업 | O11: 2823049 | P11: 115.2.02 115.2.13 115.2.12b | Q11: O | R11: N/A | S11: N/A | T11: 100.2.02 | U11: O | V11: N/A | W11: N/A | X11: N/A | Y11: N/A | Z11: N/A | AA11: N/A | AB11: KR_KPMG Dashboards - IFRS v3.1 - Media & Telecoms Industry | AC11: Information | AD11: N | AH11: V | AL11: V | AM11: V | AN11: V | AO11: V | AP11: V | AQ11: V | AR11: V | AW11: V | AX11: V | AY11: V | AZ11: V | BA11: 이현경 | BB11: hyunkyunglee@kr.kpmg.com | BE11: 이현강 | BF11: hyeonganglee@kr.kpmg.com | BG11: Cao, Leah | BH11: leahcao@kr.kpmg.com | BI11: 박성배 | BJ11: sungbaepark@kr.kpmg.com | BK11: 최진석 | BL11: jinseokchoi@kr.kpmg.com | BU11: 이준혁 | BV11: junhyeoklee@kr.kpmg.com | CG11: 김연하 | CH11: yeonhakim@kr.kpmg.com | CK11: 유용훈 | CL11: yonghoonyoo@kr.kpmg.com | CM11: 유인혁 | CN11: inhyugryu@kr.kpmg.com | CZ11: SK브로드밴드 2025년 외부감사 | DA11: 5. 작업 완료 | DD11: =IF(AF11="제외요청", "V","") | DF11: V
C12: 1658093 | D12: 5 | E12: IM2 | F12: 1000316943 | G12: SK이노베이션㈜ | H12: 1658093 | I12: SK이노베이션 2025년 외부감사 | J12: 유가증권 | L12: 석유 정제품 제조업 | M12: Energy and Natural Resources | O12: 892475 | P12: 115.2.02 | Q12: O | R12: N/A | S12: N/A | T12: 100.2.02 | U12: O | V12: N/A | W12: N/A | X12: N/A | Y12: N/A | Z12: N/A | AA12: N/A | AB12: KR_KPMG Dashboards - IFRS v3.1 - Base Industry: UpdateMay2025 | AC12: Manufacturing | AD12: Y | AI12: V | AL12: V | AM12: V | AN12: V | AO12: V | AP12: V | AQ12: V | AR12: V | AS12: V | AW12: V | AX12: V | AY12: V | AZ12: V | BA12: 이동영 | BB12: dongyounglee@kr.kpmg.com | BE12: 서은아 | BF12: eseo@kr.kpmg.com | BG12: 신재혁 | BH12: chaehyokshin@kr.kpmg.com | BK12: 이채능 | BL12: chaeneunglee@kr.kpmg.com | BU12: 정필재 | BV12: pjeong@kr.kpmg.com | CG12: 김준수 | CH12: jkim142@kr.kpmg.com | CK12: 최현지 | CL12: hyunjichoi@kr.kpmg.com | CM12: 신동민 | CN12: dshin6@kr.kpmg.com | CO12: 김윤 | CP12: ykim188@kr.kpmg.com | CQ12: 장상수 | CR12: sangsoojang@kr.kpmg.com | CS12: 한상훈 | CT12: shan24@kr.kpmg.com | CZ12: SK이노베이션 2025년 외부감사 | DA12: 5. 작업 완료 | DD12: =IF(AF12="제외요청", "V","") | DF12: V
C13: 1683431 | D13: 7 | E13: IM1 | F13: 1000325286 | G13: SK에너지 주식회사 | H13: 1683431 | I13: 2025 SK에너지 외부감사 | J13: 일반 | L13: 석유 정제품 제조업 | M13: Consumer Products, Energy and Natural Resources, Industrial Products, Retail | N13: SAP S/4 HANA | O13: 20333929 | P13: 115.2.02 115.2.13 | Q13: O | R13: N/A | S13: N/A | T13: N/A | U13: N/A | V13: N/A | W13: N/A | X13: N/A | Y13: N/A | Z13: N/A | AA13: N/A | AB13: KR_KPMG Dashboards - IFRS v3.1 - Oil & Gas Industry | AC13: Manufacturing | AD13: Y | AI13: V | AL13: V | AM13: V | AN13: V | AO13: V | AP13: V | AQ13: V | AR13: V | AS13: V | AW13: V | AX13: V | AY13: V | AZ13: V | BG13: 신재혁 | BH13: chaehyokshin@kr.kpmg.com | BI13: 강성채 | BJ13: sungchaekang@kr.kpmg.com | BK13: 변상현 | BL13: sanghyunbyun@kr.kpmg.com | BU13: 송기백 | BV13: gibaeksong@kr.kpmg.com | CG13: 탁현우 | CH13: hyunwootak@kr.kpmg.com | CK13: 곽정화 | CL13: jeonghwagwak@kr.kpmg.com | CM13: 김정태 | CN13: jkim448@kr.kpmg.com | CO13: 유지호 | CP13: jryou@kr.kpmg.com | CQ13: 황유진 | CR13: yhwang2@kr.kpmg.com | CS13: 김도형 | CT13: dkim213@kr.kpmg.com | CU13: 하창균 | CV13: changkyunha@kr.kpmg.com | CZ13: 2025 SK에너지 외부감사 | DA13: 5. 작업 완료 | DD13: =IF(AF13="제외요청", "V","") | DF13: V
C14: 1669411 | D14: 8 | E14: ICE2 | F14: 1000314822 | G14: 삼성전자 ㈜ | H14: 1669411 | I14: FY25 삼성전자 외부감사 | J14: 유가증권 | L14: 통신 및 방송장비 제조업 | O14: 104049452 | P14: 115.2.02 115.2.13 | Q14: O | R14: N/A | S14: N/A | T14: 100.2.02 | U14: O | V14: N/A | W14: N/A | X14: N/A | Y14: N/A | Z14: N/A | AA14: N/A | AB14: KR_KPMG Dashboards - IFRS v3.1 - Technology Industry | AC14: Manufacturing | AD14: Y | AI14: V | AL14: V | AM14: V | AN14: V | AO14: V | AP14: V | AQ14: V | AR14: V | AS14: V | AW14: V | AX14: V | AY14: V | AZ14: V | BA14: 이영롱 | BB14: younglonglee@kr.kpmg.com | BC14: 김수영 | BD14: skim40@kr.kpmg.com | BE14: 서은아 | BF14: eseo@kr.kpmg.com | BG14: 오헌창 | BH14: heonchangoh@kr.kpmg.com | BI14: 남상민 | BJ14: sangminnam@kr.kpmg.com | BK14: 한상현 | BL14: sanghyunhan@kr.kpmg.com | BM14: 김영선 | BN14: ykim66@kr.kpmg.com | BO14: 최이현 | BP14: yeehyunchoi@kr.kpmg.com | BQ14: 노정한 | BR14: jroh@kr.kpmg.com | BS14: 심진보 | BT14: jinboshim@kr.kpmg.com | BU14: 김지만 | BV14: jkim139@kr.kpmg.com | BW14: 한송희 | BX14: shan9@kr.kpmg.com | BY14: 김대진 | BZ14: dkim23@kr.kpmg.com | CA14: 남서영 | CB14: seoyoungnam@kr.kpmg.com | CC14: 정주희 | CD14: juheejeong@kr.kpmg.com | CE14: 민대홍 | CF14: daehongmin@kr.kpmg.com | CG14: 정성규 | CH14: sungkyujung@kr.kpmg.com | CK14: 이재하 | CL14: jaehalee@kr.kpmg.com | CZ14: FY25 삼성전자 외부감사 | DA14: 5. 작업 완료 | DD14: =IF(AF14="제외요청", "V","") | DF14: V
C15: 1658135 | D15: 9 | E15: IM2 | F15: 1000326113 | G15: SK (주) | H15: 1658135 | I15: SK(주) 2025년 외부감사 | J15: 유가증권 | L15: 지주회사 | AD15: N | AE15: 45862 | AF15: 제외요청 | AG15: 투자부문: 영업수익 및 운영비용의 거래구조가 복잡하지 않으므로 적용하지 아니함 / 사업부문: 진행매출로 적용하지 아니함 | BA15: 이동영 | BB15: dongyounglee@kr.kpmg.com | BE15: 서은아 | BF15: eseo@kr.kpmg.com | BG15: 신재혁 | BH15: chaehyokshin@kr.kpmg.com | BI15: 황재남 | BJ15: jaenamhwang@kr.kpmg.com | BK15: 최세홍 | BL15: sehongchoi@kr.kpmg.com | BM15: 이상근 | BN15: sangkeunlee@kr.kpmg.com | BU15: 정환욱 | BV15: hwanukjung@kr.kpmg.com | BW15: 이충기 | BX15: choongkilee@kr.kpmg.com | CG15: 안다영 | CH15: dayeongahn@kr.kpmg.com | CZ15: #N/A | DA15: #N/A | DD15: =IF(AF15="제외요청", "V","") -> V
A16: 박정빈 | B16: 완료 | C16: 1666520 | D16: 10 | E16: ICE2 | F16: 1000317527 | G16: 주식회사 카카오 | H16: 1666520 | I16: 2025년 카카오 외부감사 | J16: 유가증권 | L16: 포털 및 기타 인터넷 정보매개 서비스업 | M16: Media, Technology | N16: SAP | O16: 36413933 | P16: 115.2.02 115.2.13 115.2.12b | Q16: O | R16: N/A | S16: N/A | T16: N/A | U16: N/A | V16: N/A | W16: N/A | X16: N/A | Y16: N/A | Z16: N/A | AA16: N/A | AB16: KR_KPMG Dashboards - IFRS v3.1 - Media & Telecoms Industry | AC16: Information | AD16: N | AF16: 사용 | AL16: V | AW16: V | AX16: V | AY16: V | AZ16: V | BA16: 김수영 | BB16: skim40@kr.kpmg.com | BE16: 서은아 | BF16: eseo@kr.kpmg.com | BG16: 현승임 | BH16: shyun@kr.kpmg.com | BI16: 강승미 | BJ16: seungmikang@kr.kpmg.com | BK16: 이지원 | BL16: jeewonlee@kr.kpmg.com | BM16: 심진보 | BN16: jinboshim@kr.kpmg.com | BO16: 이재영 | BP16: jlee79@kr.kpmg.com | BU16: 김세모 | BV16: semokim@kr.kpmg.com | CG16: 정진우 | CH16: jjung9@kr.kpmg.com | CK16: 곽승준 | CL16: seungjunkwak@kr.kpmg.com | CM16: 이은영 | CN16: elee44@kr.kpmg.com | CO16: 윤민철 | CP16: mincheolyun@kr.kpmg.com | CQ16: 오청민 | CR16: chungminoh@kr.kpmg.com | CS16: 권혜빈 | CT16: hyebinkwon@kr.kpmg.com | CZ16: 2025년 카카오 외부감사 | DA16: 5. 작업 완료 | DC16: V | DD16: =IF(AF16="제외요청", "V","") | DF16: V
C17: 1669406 | D17: 11 | E17: ICE3 | F17: 1000317244 | G17: 네이버 주식회사 | H17: 1669406 | I17: FY25 네이버 외부감사 | J17: 유가증권 | L17: 포털 및 기타 인터넷 정보매개 서비스업 | M17: 서비스(관리 용역) 산업 , 기술 지원 산업 | N17: NEON | O17: 5875231 | P17: 115.2.02 115.2.13 115.3.01 115.2.12b | Q17: O | R17: N/A | S17: N/A | T17: 100.2.02 | U17: O | V17: N/A | W17: N/A | X17: N/A | Y17: N/A | Z17: N/A | AA17: N/A | AB17: KR_KPMG Dashboards - IFRS v3.1 - Media & Telecoms Industry | AC17: Information | AD17: N | AI17: V | AL17: V | AM17: V | AN17: V | AO17: V | AP17: V | AQ17: V | AR17: V | AW17: V | AX17: V | AY17: V | AZ17: V | BA17: 김수영 | BB17: skim40@kr.kpmg.com | BE17: 서은아 | BF17: eseo@kr.kpmg.com | BG17: 한상현 | BH17: sanghyunhan@kr.kpmg.com | BI17: 김정기 | BJ17: jungkikim@kr.kpmg.com | BK17: 최이현 | BL17: yeehyunchoi@kr.kpmg.com | BU17: 김의진 | BV17: euijinkim@kr.kpmg.com | CG17: 이성범 | CH17: seongbeomlee@kr.kpmg.com | CK17: 김부성 | CL17: boosungkim@kr.kpmg.com | CM17: 김승기 | CN17: seungkikim@kr.kpmg.com | CO17: 배슬기 | CP17: seulgibae@kr.kpmg.com | CQ17: 송경현 | CR17: ksong2@kr.kpmg.com | CS17: 김범수 | CT17: beomsookim@kr.kpmg.com | CU17: 서지원 | CV17: jseo6@kr.kpmg.com | CW17: 성현식 | CX17: hyunsikseong@kr.kpmg.com | CZ17: FY25 네이버 외부감사 | DA17: 5. 작업 완료 | DD17: =IF(AF17="제외요청", "V","") | DF17: V
A18: 김찬영 | B18: 완료 | C18: 1668904 | D18: 12 | E18: IM3 | F18: 1000317488 | G18: 현대모비스 ㈜ | H18: 1668904 | I18: FY25 현대모비스 외부감사 | J18: 유가증권 | L18: 자동차부품제조업 | O18: 700851222 | P18: 115.2.02 115.2.13 | Q18: O | R18: N/A | S18: N/A | T18: N/A | U18: N/A | V18: N/A | W18: N/A | X18: N/A | Y18: N/A | Z18: N/A | AA18: N/A | AB18: KR_KPMG Dashboards - IFRS v3.1 - Base Industry: UpdateMay2025 | AC18: Manufacturing | AD18: N | AJ18: V | AL18: V | AM18: V | AN18: V | AO18: V | AP18: V | AQ18: V | AR18: V | AW18: V | AX18: V | AY18: V | AZ18: V | BA18: 김미희 | BB18: mkim181@kr.kpmg.com | BE18: 서은아 | BF18: eseo@kr.kpmg.com | BG18: 신재혁 | BH18: chaehyokshin@kr.kpmg.com | BI18: 정양기 | BJ18: yangkijung@kr.kpmg.com | BK18: 강성채 | BL18: sungchaekang@kr.kpmg.com | BU18: 신준희 | BV18: juneheeshin@kr.kpmg.com | CG18: 정대주 | CH18: djung4@kr.kpmg.com | CZ18: FY25 현대모비스 외부감사 | DA18: 5. 작업 완료 | DD18: =IF(AF18="제외요청", "V","") | DF18: V
C19: 1668870 | D19: 13 | E19: IM3 | F19: 1000316588 | G19: (주)대한항공 | H19: 1668870 | I19: 2025 회계연도 법정감사_대한항공 | J19: 유가증권 | L19: 항공 여객 운송업 | M19: Aviation Services | N19: Oracle | O19: 30497511 | P19: 115.2.02 | Q19: O | R19: N/A | S19: N/A | T19: N/A | U19: N/A | V19: N/A | W19: N/A | X19: N/A | Y19: N/A | Z19: N/A | AA19: N/A | AB19: KR_KPMG Dashboards - IFRS v3.1 - Base Industry: UpdateMay2025 | AC19: Transportation and Warehousing | AD19: N | AI19: V | AL19: V | AM19: V | AN19: V | AO19: V | AP19: V | AQ19: V | AR19: V | AS19: V | AW19: V | AX19: V | AY19: V | AZ19: V | BA19: 이채영 | BB19: clee46@kr.kpmg.com | BE19: 서은아 | BF19: eseo@kr.kpmg.com | BG19: 오헌창 | BH19: heonchangoh@kr.kpmg.com | BI19: 황재남 | BJ19: jaenamhwang@kr.kpmg.com | BK19: 신동준 | BL19: dongjunshin@kr.kpmg.com | BU19: 김상우 | BV19: skim56@kr.kpmg.com | CG19: 고요섭 | CH19: yosupgo@kr.kpmg.com | CM19: 김민지 | CN19: mkim196@kr.kpmg.com | CZ19: 2025 회계연도 법정감사_대한항공 | DA19: 5. 작업 완료 | DD19: =IF(AF19="제외요청", "V","") | DF19: V
A20: 박정빈 | B20: 완료 | C20: 1668853 | D20: 14 | E20: IM3 | F20: 1000316585 | G20: 아시아나항공 | H20: 1668853 | I20: [아시아나항공] 2025년 지정 감사 | J20: 유가증권 | L20: 항공 여객 운송업 | M20: Aviation / Services | N20: SAP S/4 HANA | O20: 13817517 | P20: 115.2.13 115.3.01 | Q20: O | R20: N/A | S20: N/A | T20: N/A | U20: N/A | V20: N/A | W20: N/A | X20: N/A | Y20: N/A | Z20: N/A | AA20: N/A | AB20: KR_KPMG Dashboards - IFRS v3.1 - Base Industry: UpdateMay2025 | AC20: Transportation and Warehousing | AD20: N | AI20: V | AK20: V | AL20: V | AM20: V | AN20: V | AO20: V | AP20: V | AQ20: V | AR20: V | AS20: V | AW20: V | AX20: V | AY20: V | AZ20: V | BA20: 노민경 | BB20: minkyungro@kr.kpmg.com | BE20: 서은아 | BF20: eseo@kr.kpmg.com | BG20: 오헌창 | BH20: heonchangoh@kr.kpmg.com | BI20: 이채능 | BJ20: chaeneunglee@kr.kpmg.com | BK20: 백명종 | BL20: mbaek@kr.kpmg.com | BU20: 조윤기 | BV20: yungicho@kr.kpmg.com | CG20: 오재욱 | CH20: jaeukoh@kr.kpmg.com | CK20: 조영진 | CL20: ycho14@kr.kpmg.com | CZ20: [아시아나항공] 2025년 지정 감사 | DA20: 5. 작업 완료 | DD20: =IF(AF20="제외요청", "V","") | DF20: V
C21: 1667371 | D21: 15 | E21: IM1 | F21: 1000314665 | G21: 삼성바이오로직스 주식회사 | H21: 1667371 | I21: 삼성바이오로직스 외부감사_FY25 | J21: 유가증권 | L21: 기초 의약 물질 제조업 | M21: Industrial Products, Healthcare | N21: SAP | O21: 1146540 | P21: 115.2.02 115.2.13 115.3.01 | Q21: O | R21: N/A | S21: N/A | T21: 100.2.02 | U21: O | V21: N/A | W21: N/A | X21: N/A | Y21: N/A | Z21: N/A | AA21: N/A | AB21: KR_KPMG Dashboards - IFRS v3.1 - Healthcare Industry | AC21: Manufacturing | AD21: N | AI21: V | AL21: V | AM21: V | AN21: V | AO21: V | AP21: V | AQ21: V | AR21: V | AS21: V | AW21: V | AX21: V | AY21: V | AZ21: V | BA21: 이채영 | BB21: clee46@kr.kpmg.com | BE21: 이현강 | BF21: hyeonganglee@kr.kpmg.com | BG21: 현승임 | BH21: shyun@kr.kpmg.com | BI21: 임근구 | BJ21: gleem@kr.kpmg.com | BK21: 나재광 | BL21: jra@kr.kpmg.com | BU21: 김수연 | BV21: suyeonkim@kr.kpmg.com | CG21: 임혁순 | CH21: hyim@kr.kpmg.com | CK21: 백진주 | CL21: jinjubaek@kr.kpmg.com | CZ21: 삼성바이오로직스 외부감사_FY25 | DA21: 5. 작업 완료 | DD21: =IF(AF21="제외요청", "V","") | DF21: V
C22: 1683436 | D22: 16 | E22: ICE3 | F22: 1000325445 | G22: 삼성디스플레이 주식회사 | H22: 1683436 | I22: FY25_삼성디스플레이_외부감사 | J22: 일반 | L22: 액정 표시장치 제조업 | AB22: KR_KPMG Dashboards - IFRS v3.1 - Technology Industry | AC22: Manufacturing | AD22: Y | AF22: 사용 | AI22: V | AL22: V | AM22: V | AN22: V | AO22: V | AP22: V | AQ22: V | AR22: V | AW22: V | AX22: V | AY22: V | AZ22: V | BI22: 설하영 | BJ22: hsul@kr.kpmg.com | BK22: 설유진 | BL22: yseol@kr.kpmg.com | BU22: 장진 | BV22: jinjang@kr.kpmg.com | CG22: 이은상 | CH22: eunsanglee@kr.kpmg.com | CZ22: FY25_삼성디스플레이_외부감사 | DA22: 5. 작업 완료 | DC22: V | DD22: =IF(AF22="제외요청", "V","") | DF22: V
A23: 박정빈 | B23: 완료 | C23: 1663086 | D23: 17 | E23: IM1 | F23: 1000325538 | G23: SK 네트웍스 ㈜ | H23: 1663086 | I23: FY2025_SK네트웍스_법정감사 | J23: 유가증권 | L23: 기타 전문 도매업 | M23: Consumer Products , Retail, Services, Telecommunications | N23: SAP | O23: 3885124 | P23: 115.2.02 115.2.12b 115.2.13 115.3.01 | Q23: O | R23: N/A | S23: N/A | T23: N/A | U23: N/A | V23: N/A | W23: N/A | X23: N/A | Y23: N/A | Z23: N/A | AA23: N/A | AB23: KR_KPMG Dashboards - IFRS v3.1 - Retail Industry | AC23: Wholesale Trade | AD23: Y | AI23: V | AL23: V | AM23: V | AN23: V | AO23: V | AP23: V | AQ23: V | AR23: V | AW23: V | AX23: V | AY23: V | AZ23: V | BA23: 황인영 | BB23: ihwang7@kr.kpmg.com | BE23: 이현강 | BF23: hyeonganglee@kr.kpmg.com | BG23: 신재혁 | BH23: chaehyokshin@kr.kpmg.com | BI23: 도정욱 | BJ23: jungwookdo@kr.kpmg.com | BK23: 이주영 | BL23: jooyounglee@kr.kpmg.com | BU23: 박율철 | BV23: yulcheolpark@kr.kpmg.com | CG23: 천의성 | CH23: euiseongcheon@kr.kpmg.com | CK23: 손인수 | CL23: insooson@kr.kpmg.com | CM23: 이미현 | CN23: mihyeonlee@kr.kpmg.com | CO23: 이상원 | CP23: slee227@kr.kpmg.com | CZ23: FY2025_SK네트웍스_법정감사 | DA23: 5. 작업 완료 | DD23: =IF(AF23="제외요청", "V","") | DF23: V
C24: 1683711 | D24: 18 | E24: ICE2 | F24: 1000844981 | G24: 두나무 주식회사 | H24: 1683711 | I24: 두나무_외부감사_FY2025 | J24: 일반 | L24: 정보서비스업 | AB24: KR_KPMG Dashboards - IFRS v3.1 - Banking Industry | AC24: Finance and Insurance | AD24: N | AE24: 45891 | AF24: 제외요청 | AG24: 적용 시 비효율적이라 판단 | BA24: 김수영 | BB24: skim40@kr.kpmg.com | BE24: 서은아 | BF24: eseo@kr.kpmg.com | BG24: 오헌창 | BH24: heonchangoh@kr.kpmg.com | BI24: 안창범 | BJ24: cahn@kr.kpmg.com | BK24: 최연택 | BL24: yeontaekchoi@kr.kpmg.com | BM24: 신문철 | BN24: moonchulshin@kr.kpmg.com | BU24: 김현준 | BV24: hkim108@kr.kpmg.com | CG24: 한민규 | CH24: mingyuhan@kr.kpmg.com | CZ24: #N/A | DA24: #N/A | DD24: =IF(AF24="제외요청", "V","") -> V
C25: 1667197 | D25: 19 | E25: CM2 | F25: 1000314625 | G25: 롯데지주 주식회사 | H25: 1667197 | I25: 롯데지주 2025년 외부감사(지정) | J25: 유가증권 | L25: 지주회사 | AB25: KR_KPMG Dashboards - IFRS v3.1 - Banking Industry | AC25: Management of Companies and Enterprises | AD25: N | AE25: 45902 | AF25: 제외요청 | AG25: 지주회사로 매출의 경우 SR이며, 비용의 경우 양적/질적으로 중요한 샘플은 specific으로 확인하고 있고, 잔여모집단에 대해서만 mus로 샘플을 추출하여 AITS 사용 실익이 적을 것으로 보임 | BA25: 김미희 | BB25: mkim181@kr.kpmg.com | BE25: 이현강 | BF25: hyeonganglee@kr.kpmg.com | BG25: 오헌창 | BH25: heonchangoh@kr.kpmg.com | BI25: 현윤호 | BJ25: yhyun@kr.kpmg.com | BK25: 김시우 | BL25: siwookim@kr.kpmg.com | BU25: 오승재 | BV25: seungjaeoh@kr.kpmg.com | CG25: 이광수 | CH25: kwangsulee@kr.kpmg.com | CZ25: #N/A | DA25: #N/A | DD25: =IF(AF25="제외요청", "V","") -> V
C26: 1670326 | D26: 20 | E26: ICE3 | F26: 1000314621 | G26: 넷마블 주식회사 | H26: 1670326 | I26: FY25 넷마블 외부감사 | J26: 유가증권 | L26: 게임 소프트웨어 개발 및 공급업 | M26: 서비스(관리 용역) 산업, 통신 산업 | N26: SAP | O26: 400432 | P26: 115.2.02 | Q26: O | R26: N/A | S26: N/A | T26: 100.2.02 | U26: O | V26: N/A | W26: N/A | X26: N/A | Y26: N/A | Z26: N/A | AA26: N/A | AB26: KR_KPMG Dashboards - IFRS v3.1 - Media & Telecoms Industry | AC26: Information | AD26: N | AL26: V | AM26: V | AN26: V | AO26: V | AP26: V | AQ26: V | AR26: V | AS26: V | AW26: V | AX26: V | AY26: V | AZ26: V | BA26: 이영롱 | BB26: younglonglee@kr.kpmg.com | BE26: 서은아 | BF26: eseo@kr.kpmg.com | BG26: 오헌창 | BH26: heonchangoh@kr.kpmg.com | BI26: 윤주헌 | BJ26: joohunyoon@kr.kpmg.com | BK26: 김익찬 | BL26: ikchankim@kr.kpmg.com | BU26: 이윤아 | BV26: yoonahlee@kr.kpmg.com | CG26: 이형철 | CH26: hyeongcheollee@kr.kpmg.com | CK26: 김상현 | CL26: skim257@kr.kpmg.com | CM26: 이민석 | CN26: mlee96@kr.kpmg.com | CZ26: FY25 넷마블 외부감사 | DA26: 5. 작업 완료 | DD26: =IF(AF26="제외요청", "V","") | DF26: V
C27: 1669412 | D27: 21 | E27: IM1 | F27: 1000953186 | G27: 에이치디현대중공업 주식회사 | H27: 1669412 | I27: FY2025 HD현대중공업 주식회사 외부감사 | J27: 유가증권 | L27: 선박건조업 | AD27: N | AE27: 45873 | AF27: 제외요청 | AG27: 대부분이 진행기준으로 매출과 원가 90% 이상이 SR | BA27: 김미희 | BB27: mkim181@kr.kpmg.com | BE27: 이현강 | BF27: hyeonganglee@kr.kpmg.com | BG27: 김신 | BH27: skim137@kr.kpmg.com | BI27: 노상호 | BJ27: sanghoroh@kr.kpmg.com | BK27: 전원표 | BL27: wjeon@kr.kpmg.com | BU27: 김성일 | BV27: seongilkim@kr.kpmg.com | BW27: 송기백 | BX27: gibaeksong@kr.kpmg.com | CG27: 탁현우 | CH27: hyunwootak@kr.kpmg.com | CZ27: #N/A | DA27: #N/A | DD27: =IF(AF27="제외요청", "V","") -> V
C28: 1668586 | D28: 22 | E28: CM2 | F28: 1000810814 | G28: 롯데웰푸드㈜ | H28: 1668586 | I28: FY2025 롯데웰푸드 외부감사 | J28: 유가증권 | L28: 기타 식품 제조업 | AB28: KR_KPMG Dashboards - IFRS v3.1 - Base Industry: UpdateMay2025 | AC28: Manufacturing | AD28: N | AE28: 45874 | AF28: 제외요청 | AG28: 1. 수익 : GL이 아닌 유통채널별 매출전표로 위험평가 및 실증절차를 수행하여 AITS 적용이 어려움. 2. 매출원가 : 재고자산으로 포함되는 원가로 적용 불가 3. 비용 : 실익이 낮아 미적용 | BA28: 김미희 | BB28: mkim181@kr.kpmg.com | BE28: 이현강 | BF28: hyeonganglee@kr.kpmg.com | BG28: 이승훈 | BH28: seunghoonlee@kr.kpmg.com | BI28: 현윤호 | BJ28: yhyun@kr.kpmg.com | BK28: 정현진 | BL28: hchung@kr.kpmg.com | BU28: 이치백 | BV28: clee60@kr.kpmg.com | CG28: 이재근 | CH28: jaekeunlee@kr.kpmg.com | CZ28: #N/A | DA28: #N/A | DD28: =IF(AF28="제외요청", "V","") -> V
C29: 1660660 | D29: 23 | E29: IM4 | F29: 1000326094 | G29: 팬오션 주식회사 | H29: 1660660 | I29: [팬오션] FY25 외부감사 (주기적 지정) | J29: 유가증권 | L29: 외항 화물 운송업 | M29: Services | N29: Oracle | O29: 5158962 | P29: 115.2.02 | Q29: O | R29: N/A | S29: N/A | T29: N/A | U29: N/A | V29: N/A | W29: N/A | X29: N/A | Y29: N/A | Z29: N/A | AA29: N/A | AB29: KR_KPMG Dashboards - IFRS v3.1 - Base Industry: UpdateMay2025 | AC29: Transportation and Warehousing | AD29: N | AL29: V | AM29: V | AN29: V | AO29: V | AP29: V | AQ29: V | AR29: V | BA29: 김미희 | BB29: mkim181@kr.kpmg.com | BE29: 이현강 | BF29: hyeonganglee@kr.kpmg.com | BG29: 지가현 | BH29: gahyunji@kr.kpmg.com | BI29: 최연석 | BJ29: ychoi@kr.kpmg.com | BK29: 김성배 | BL29: sungbaekim@kr.kpmg.com | BU29: 남종수 | BV29: jongsunam@kr.kpmg.com | CG29: 이요셉 | CH29: jlee176@kr.kpmg.com | CK29: 이정훈 | CL29: jlee520@kr.kpmg.com | CZ29: [팬오션] FY25 외부감사 (주기적 지정) | DA29: 5. 작업 완료 | DD29: =IF(AF29="제외요청", "V","") | DF29: V
C30: 1682164 | D30: 24 | E30: IM3 | F30: 1000314559 | G30: 에스케이지오센트릭 주식회사 | H30: 1682164 | I30: 에스케이지오센트릭 주식회사 FY2025 외부감사 | J30: 일반 | L30: 석유화학계 기초 화학물질 제조업 | M30: Energy and Natural Resources | N30: SAP | O30: 3311595 | P30: 115.2.13 | Q30: O | R30: N/A | S30: N/A | T30: N/A | U30: N/A | V30: N/A | W30: N/A | X30: N/A | Y30: N/A | Z30: N/A | AA30: N/A | AB30: KR_KPMG Dashboards - IFRS v3.1 - Oil & Gas Industry | AC30: Manufacturing | AD30: N | AE30: 45965 | AF30: 제외요청 | AG30: 위험하지 않은 전표들이 위험전표로 식별된 경우가 많음 | AL30: V | AM30: V | AN30: V | AO30: V | AP30: V | AQ30: V | AR30: V | AS30: V | BA30: 황인영 | BB30: ihwang7@kr.kpmg.com | BG30: 신재혁 | BH30: chaehyokshin@kr.kpmg.com | BI30: 차용재 | BJ30: ycha@kr.kpmg.com | BK30: 이종상 | BL30: jongsanglee@kr.kpmg.com | BU30: 정준영 | BV30: junyoungjung@kr.kpmg.com | CG30: 황서연 | CH30: seoyeonhwang@kr.kpmg.com | CK30: 이병관 | CL30: byeonggwalee@kr.kpmg.com | CZ30: 에스케이지오센트릭 주식회사 FY2025 외부감사 | DA30: 5. 작업 완료 | DD30: =IF(AF30="제외요청", "V","") -> V
A31: 박정빈 | B31: 완료 | C31: 1659929 | D31: 25 | E31: CM1 | F31: 1000326018 | G31: 하이트진로 ㈜ | H31: 1659929 | I31: FY2025 하이트진로 주식회사 외부감사 | J31: 유가증권 | L31: 소비재 | M31: Consumer Products | N31: Oracle | O31: 15703604 | P31: 115.2.02 115.2.13 | Q31: O | R31: N/A | S31: N/A | T31: N/A | U31: N/A | V31: N/A | W31: N/A | X31: N/A | Y31: N/A | Z31: N/A | AA31: N/A | AB31: KR_KPMG Dashboards - IFRS v3.1 - Retail Industry | AC31: Manufacturing | AD31: Y | AL31: V | AM31: V | AN31: V | AO31: V | AP31: V | AQ31: V | AR31: V | AT31: V | AU31: V | AW31: V | AX31: V | AY31: V | AZ31: V | BA31: 홍민정 | BB31: minjunghong@kr.kpmg.com | BE31: 이현강 | BF31: hyeonganglee@kr.kpmg.com | BG31: 현승임 | BH31: shyun@kr.kpmg.com | BI31: 정현진 | BJ31: hchung@kr.kpmg.com | BK31: 김중규 | BL31: joongkyukim@kr.kpmg.com | BU31: 김예현 | BV31: yaehyeonkim@kr.kpmg.com | CG31: 강건국 | CH31: konkukkang@kr.kpmg.com | CK31: 김정 | CL31: jkim444@kr.kpmg.com | CM31: 김준회 | CN31: junhoekim@kr.kpmg.com | CZ31: FY2025 하이트진로 주식회사 외부감사 | DA31: 5. 작업 완료 | DD31: =IF(AF31="제외요청", "V","") | DF31: V
C32: 1684186 | D32: 26 | E32: IM2 | F32: 1000315539 | G32: GS칼텍스㈜ | H32: 1684186 | I32: GSC FY25 회계감사 | J32: 일반 | L32: 원유 정제처리업 | M32: Energy and Natural Resources | N32: SAP ERP 6.0용 EHP6 | O32: 25626995 | P32: 115.2.02 115.2.13 | Q32: O | R32: N/A | S32: N/A | T32: 100.2.02 | U32: O | V32: N/A | W32: N/A | X32: N/A | Y32: N/A | Z32: N/A | AA32: N/A | AB32: KR_KPMG Dashboards - IFRS v3.1 - Oil & Gas Industry | AC32: Manufacturing | AD32: N | AI32: V | AL32: V | AM32: V | AN32: V | AO32: V | AP32: V | AQ32: V | AR32: V | AS32: V | BA32: 홍민정 | BB32: minjunghong@kr.kpmg.com | BE32: 이현강 | BF32: hyeonganglee@kr.kpmg.com | BG32: 현승임 | BH32: shyun@kr.kpmg.com | BI32: 나재광 | BJ32: jra@kr.kpmg.com | BK32: 정재욱 | BL32: jjoung@kr.kpmg.com | BU32: 주예솔 | BV32: yeasolju@kr.kpmg.com | CG32: 김찬양 | CH32: ckim12@kr.kpmg.com | CK32: 민정식 | CL32: jungsikmin@kr.kpmg.com | CM32: 정윤호 | CN32: yunhojeong@kr.kpmg.com | CZ32: GSC FY25 회계감사 | DA32: 5. 작업 완료 | DD32: =IF(AF32="제외요청", "V","") | DF32: V
C33: 1657107 | D33: 27 | E33: ICE2 | F33: 1000998259 | G33: 크래프톤 | H33: 1657107 | I33: 크래프톤 FY25 외부감사 | J33: 유가증권 | L33: 게임 소프트웨어 개발 및 공급업 | M33: Services | N33: SAP | O33: 675766 | P33: N/A | Q33: N/A | R33: N/A | S33: N/A | T33: 100.2.02 | U33: O | V33: N/A | W33: N/A | X33: N/A | Y33: N/A | Z33: N/A | AA33: N/A | AB33: KR_KPMG Dashboards - IFRS v3.1 - Media & Telecoms Industry | AC33: Information | AD33: N | AL33: V | AM33: V | AN33: V | AO33: V | AP33: V | AQ33: V | AR33: V | AW33: V | AX33: V | AY33: V | AZ33: V | BA33: 홍민정 | BB33: minjunghong@kr.kpmg.com | BG33: 김신 | BH33: skim137@kr.kpmg.com | BI33: 박성배 | BJ33: sungbaepark@kr.kpmg.com | BK33: 최연택 | BL33: yeontaekchoi@kr.kpmg.com | BU33: 정지훈 | BV33: jjung32@kr.kpmg.com | CG33: 최성환 | CH33: seonghwanchoi@kr.kpmg.com | CK33: 이다은 | CL33: dlee134@kr.kpmg.com | CZ33: 크래프톤 FY25 외부감사 | DA33: 5. 작업 완료 | DD33: =IF(AF33="제외요청", "V","") | DF33: V
C34: 1660170 | D34: 28 | E34: IGH | F34: 1000315188 | G34: (주) 제일기획 | H34: 1660170 | I34: [제일기획] FY2025 지정감사 | J34: 유가증권 | L34: 광고 대행업 | M34: Media | N34: SAP | O34: 1099438 | P34: 115.2.02 115.2.12b 115.2.13 115.3.01 | Q34: O | R34: 100.2.02 | S34: O | T34: N/A | U34: N/A | V34: N/A | W34: N/A | X34: N/A | Y34: N/A | Z34: N/A | AA34: N/A | AB34: KR_KPMG Dashboards - IFRS v3.1 - Media & Telecoms Industry | AC34: Information | AD34: Y | AI34: V | AL34: V | AM34: V | AN34: V | AO34: V | AP34: V | AQ34: V | AR34: V | AS34: V | AW34: V | AX34: V | AY34: V | AZ34: V | BA34: 노민경 | BB34: minkyungro@kr.kpmg.com | BE34: 이현강 | BF34: hyeonganglee@kr.kpmg.com | BG34: 김신 | BH34: skim137@kr.kpmg.com | BI34: 조일상 | BJ34: ijo@kr.kpmg.com | BK34: 이덕영 | BL34: deokyeonglee@kr.kpmg.com | BU34: 박종근 | BV34: jongkeunpark@kr.kpmg.com | CG34: 박태선 | CH34: taesunpark@kr.kpmg.com | CK34: 정진우 | CL34: jjung28@kr.kpmg.com | CM34: 최진환 | CN34: jinhwanchoi@kr.kpmg.com | CZ34: [제일기획] FY2025 지정감사 | DA34: 5. 작업 완료 | DD34: =IF(AF34="제외요청", "V","") | DF34: V
A35: 박정빈 | B35: 완료 | C35: 1660760 | D35: 29 | E35: IM2 | F35: 1000325863 | G35: 주식회사 E1 | H35: 1660760 | I35: E1 2025 회계감사(주기적지정) | J35: 유가증권 | L35: 기체연료 및 관련제품 도매업 | M35: Energy and Natural Resources | N35: SAP | O35: 5795399 | P35: 115.2.02 115.2.13 | Q35: O | R35: N/A | S35: N/A | T35: 100.2.02 | U35: O | V35: N/A | W35: N/A | X35: N/A | Y35: N/A | Z35: N/A | AA35: N/A | AB35: KR_KPMG Dashboards - IFRS v3.1 - Retail Industry | AC35: Wholesale Trade | AD35: Y | AI35: V | AL35: V | AM35: V | AN35: V | AO35: V | AP35: V | AQ35: V | AR35: V | AS35: V | AW35: V | AX35: V | AY35: V | AZ35: V | BA35: 노민경 | BB35: minkyungro@kr.kpmg.com | BE35: 이현강 | BF35: hyeonganglee@kr.kpmg.com | BG35: 신재혁 | BH35: chaehyokshin@kr.kpmg.com | BI35: 지동현 | BJ35: dchi@kr.kpmg.com | BK35: 조화수 | BL35: hwasoocho@kr.kpmg.com | BU35: 주예솔 | BV35: yeasolju@kr.kpmg.com | CG35: 김영일 | CH35: ykim47@kr.kpmg.com | CK35: 이승윤 | CL35: slee309@kr.kpmg.com | CZ35: E1 2025 회계감사(주기적지정) | DA35: 5. 작업 완료 | DD35: =IF(AF35="제외요청", "V","") | DF35: V
A36: 박정빈 | B36: 완료 | C36: 1669115 | D36: 30 | E36: CM1 | F36: 1000317405 | G36: 주식회사 현대백화점 | H36: 1669115 | I36: 현대백화점 2025년 외부감사 | J36: 유가증권 | L36: 유통업 | M36: Consumer Products | N36: HIFI (Legacy) | O36: 6016089 | P36: 115.2.13 | Q36: O | R36: N/A | S36: N/A | T36: 100.2.02 | U36: O | V36: N/A | W36: N/A | X36: N/A | Y36: N/A | Z36: N/A | AA36: N/A | AB36: KR_KPMG Dashboards - IFRS v3.1 - Retail Industry | AC36: Retail Trade | AD36: Y | AI36: V | AL36: V | AM36: V | AN36: V | AO36: V | AP36: V | AQ36: V | AR36: V | AW36: V | AX36: V | AY36: V | AZ36: V | BA36: 이채영 | BB36: clee46@kr.kpmg.com | BG36: 지가현 | BH36: gahyunji@kr.kpmg.com | BI36: 장현민 | BJ36: hyunminjang@kr.kpmg.com | BK36: 이상기 | BL36: sangkilee@kr.kpmg.com | BU36: 이세현 | BV36: sehyunlee@kr.kpmg.com | CG36: 김윤 | CH36: ykim85@kr.kpmg.com | CK36: 유현석 | CL36: hyunsukyoo@kr.kpmg.com | CM36: 박정주 | CN36: jungjoopark@kr.kpmg.com | CZ36: 현대백화점 2025년 외부감사 | DA36: 5. 작업 완료 | DD36: =IF(AF36="제외요청", "V","") | DF36: V
C37: 1664821 | D37: 31 | E37: IM2 | F37: 1000325221 | G37: 엘에스일렉트릭㈜ | H37: 1664821 | I37: 2025년 LS일렉트릭 지정감사 | J37: 유가증권 | L37: 전기회로 개폐, 보호장치 제조업 | AB37: KR_KPMG Dashboards - IFRS v3.1 - Base Industry: UpdateMay2025 | AC37: Manufacturing | AD37: N | AE37: 45958 | AF37: 제외요청 | AG37: 하나의 계정으로 진행매출과 일반매출 같이 분개. 비용은 금액적으로 유의하지 않아 절차 필요하지 않음 | AL37: V | AM37: V | AN37: V | AO37: V | AP37: V | BA37: 김수연 | BB37: sooyeonkim@kr.kpmg.com | BE37: 이현강 | BF37: hyeonganglee@kr.kpmg.com | BG37: 이승훈 | BH37: seunghoonlee@kr.kpmg.com | BI37: 이경석 | BJ37: kyungsuklee@kr.kpmg.com | BK37: 노상호 | BL37: sanghoroh@kr.kpmg.com | BU37: 한정희 | BV37: jeongheehan@kr.kpmg.com | CG37: 이창우 | CH37: clee45@kr.kpmg.com | CZ37: 2025년 LS일렉트릭 지정감사 | DA37: 9. 서비스 취소 | DD37: =IF(AF37="제외요청", "V","") -> V
C38: 1670498 | D38: 32 | E38: IM1 | F38: 1000316274 | G38: 에스케이씨 (주) | H38: 1670498 | I38: 2025년 SKC 법정감사 | J38: 유가증권 | L38: 기타 화학제품 제조업 | AD38: N | AE38: 45874 | AF38: 제외요청 | AG38: 순수 지주사임에 따라 MUS 불필요 | BA38: 엄정복 | BB38: juhm@kr.kpmg.com | BE38: 이현강 | BF38: hyeonganglee@kr.kpmg.com | BG38: 한상현 | BH38: sanghyunhan@kr.kpmg.com | BI38: 최연석 | BJ38: ychoi@kr.kpmg.com | BK38: 변상현 | BL38: sanghyunbyun@kr.kpmg.com | BU38: 원영인 | BV38: younginwon@kr.kpmg.com | CG38: 차순석 | CH38: sunseokcha@kr.kpmg.com | CZ38: #N/A | DA38: #N/A | DD38: =IF(AF38="제외요청", "V","") -> V
C39: 1668840 | D39: 33 | E39: IM3 | F39: 1000317452 | G39: 케이지모빌리티㈜ | H39: 1668840 | I39: FY25 KG 모빌리티_지정감사 | J39: 유가증권 | L39: 자동차용 엔진 및 자동차 제조업 | M39: Automotive | N39: SAP | O39: 96686944 | P39: 115.3.01 115.2.02 115.2.13 | Q39: O | R39: N/A | S39: N/A | T39: N/A | U39: N/A | V39: N/A | W39: N/A | X39: N/A | Y39: N/A | Z39: N/A | AA39: N/A | AB39: KR_KPMG Dashboards - IFRS v3.1 - Base Industry: UpdateMay2025 | AC39: Manufacturing | AD39: N | AI39: V | AL39: V | AM39: V | AN39: V | AO39: V | AP39: V | AQ39: V | AR39: V | AS39: V | AW39: V | AX39: V | AY39: V | AZ39: V | BA39: 이채영 | BB39: clee46@kr.kpmg.com | BE39: 이현강 | BF39: hyeonganglee@kr.kpmg.com | BG39: 김신 | BH39: skim137@kr.kpmg.com | BI39: 나재광 | BJ39: jra@kr.kpmg.com | BK39: 이종상 | BL39: jongsanglee@kr.kpmg.com | BU39: 정준영 | BV39: junyoungjung@kr.kpmg.com | CG39: 박승현 | CH39: seunghyunpark@kr.kpmg.com | CK39: 김휘재 | CL39: hweejaekim@kr.kpmg.com | CM39: 김재원 | CN39: jkim442@kr.kpmg.com | CO39: 최재영 | CP39: jchoi103@kr.kpmg.com | CQ39: 이성민 | CR39: slee424@kr.kpmg.com | CZ39: FY25 KG 모빌리티_지정감사 | DA39: 5. 작업 완료 | DD39: =IF(AF39="제외요청", "V","") | DF39: V
A40: 김찬영 | B40: 완료 | C40: 1667049 | D40: 34 | E40: ICE3 | F40: 1000317380 | G40: (주)엘앤에프 | H40: 1667049 | I40: 엘앤에프 FY25 지정감사 | J40: 유가증권 | L40: 운송장비용 이차전지 제조업 | M40: Industrial Products | N40: SAP | O40: 1338782 | P40: 115.3.01 115.2.02 115.2.13 | Q40: O | R40: N/A | S40: N/A | T40: 100.2.02 | U40: O | V40: N/A | W40: N/A | X40: N/A | Y40: N/A | Z40: N/A | AA40: N/A | AB40: KR_KPMG Dashboards - IFRS v3.1 - Base Industry: UpdateMay2025 | AC40: Manufacturing | AD40: N | AL40: V | AM40: V | AN40: V | AO40: V | AP40: V | AQ40: V | AR40: V | AS40: V | AW40: V | AX40: V | AY40: V | AZ40: V | BA40: 전혜지 | BB40: hjeon6@kr.kpmg.com | BE40: 이현강 | BF40: hyeonganglee@kr.kpmg.com | BG40: 김신 | BH40: skim137@kr.kpmg.com | BI40: 최세홍 | BJ40: sehongchoi@kr.kpmg.com | BK40: 강인혜 | BL40: ikang@kr.kpmg.com | BU40: 이동규 | BV40: donggyulee@kr.kpmg.com | CG40: 최민기 | CH40: minkichoi@kr.kpmg.com | CK40: 김다정 | CL40: dajungkim@kr.kpmg.com | CM40: 김아정 | CN40: ajungkim@kr.kpmg.com | CZ40: 엘앤에프 FY25 지정감사 | DA40: 5. 작업 완료 | DD40: =IF(AF40="제외요청", "V","") | DF40: V
C41: 1669145 | D41: 35 | E41: ICE1 | F41: 1001210610 | G41: 에스케이스퀘어 주식회사 | H41: 1669145 | I41: SK스퀘어 FY25 외부감사 | J41: 유가증권 | L41: 지주회사 | AB41: KR_KPMG Dashboards - IFRS v3.1 - Banking Industry | AC41: Management of Companies and Enterprises | AD41: N | AE41: 45960 | AF41: 제외요청 | AG41: 지주회사로 AITS 적용할만한 RMM 없음 | BA41: 이현경 | BB41: hyunkyunglee@kr.kpmg.com | BE41: 이현강 | BF41: hyeonganglee@kr.kpmg.com | BG41: 오헌창 | BH41: heonchangoh@kr.kpmg.com | BI41: 신문철 | BJ41: moonchulshin@kr.kpmg.com | BK41: 박성배 | BL41: sungbaepark@kr.kpmg.com | BU41: 양호철 | BV41: hocheolyang@kr.kpmg.com | CG41: 양호철 | CH41: hocheolyang@kr.kpmg.com | CZ41: #N/A | DA41: #N/A | DD41: =IF(AF41="제외요청", "V","") -> V
C42: 1661219 | D42: 36 | E42: IM1 | F42: 1000315889 | G42: 에이치디현대미포 주식회사 | H42: 1661219 | I42: FY2025_HD현대미포_지정감사 | J42: 유가증권 | L42: 선박 및 수상 부유 구조물 건조업 | AD42: N | AE42: 45874 | AF42: 제외요청 | AG42: 매출은 모든 CAR이 Base보다 위험하다고 평가하여 적용 불가. 비용은 샘플수가 적음(30건 미만) | BA42: 노민경 | BB42: minkyungro@kr.kpmg.com | BE42: 서은아 | BF42: eseo@kr.kpmg.com | BG42: 오헌창 | BH42: heonchangoh@kr.kpmg.com | BI42: 이채능 | BJ42: chaeneunglee@kr.kpmg.com | BK42: 차용재 | BL42: ycha@kr.kpmg.com | BU42: 김성일 | BV42: seongilkim@kr.kpmg.com | CG42: 황기명 | CH42: gimyeonghwang@kr.kpmg.com | CZ42: #N/A | DA42: #N/A | DD42: =IF(AF42="제외요청", "V","") -> V
...

Sheet 이메일 주소(전체)
B2: jaenamhwang@kr.kpmg.com, sehongchoi@kr.kpmg.com, sangkeunlee@kr.kpmg.com, hwanukjung@kr.kpmg.com, choongkilee@kr.kpmg.com, dayeongahn@kr.kpmg.com | S2: jaenamhwang@kr.kpmg.com, sehongchoi@kr.kpmg.com, sangkeunlee@kr.kpmg.com, hwanukjung@kr.kpmg.com, choongkilee@kr.kpmg.com, dayeongahn@kr.kpmg.com | T2: =SUBSTITUTE(S2,", ","; ") -> jaenamhwang@kr.kpmg.com; sehongchoi@kr.kpmg.com; sangkeunlee@kr.kpmg.com; hwanukjung@kr.kpmg.com; choongkilee@kr.kpmg.com; dayeongahn@kr.kpmg.com | U2: {=_xlfn.LET(_xlpm.r,T2:T192,_xlpm.repl,SUBSTITUTE(_xlpm.r,",","; "),_xlpm.all,_xlfn.TEXTSPLIT(_xlfn.TEXTJOIN(";",TRUE,_xlpm.repl),";"),_xlpm.clean,TRIM(_xlpm.all),_xlpm.noempty,_xlfn._xlws.FILTER(_xlpm.clean,_xlpm.clean<>""),_xlpm.dedup,_xlfn.UNIQUE(_xlpm.noempty),_xlfn.TEXTJOIN("; ",TRUE,_xlpm.dedup))} -> jaenamhwang@kr.kpmg.com; sehongchoi@kr.kpmg.com; sangkeunlee@kr.kpmg.com; hwanukjung@kr.kpmg.com; choongkilee@kr.kpmg.com; dayeongahn@kr.kpmg.com; seungmikang@kr.kpmg.com; jeewonlee@kr.kpmg.com; jinboshim@kr.kpmg.com; jlee79@kr.kpmg.com; semokim@kr.kpmg.com; jjung9@kr.kpmg.com; jungkikim@kr.kpmg.com; yeehyunchoi@kr.kpmg.com; euijinkim@kr.kpmg.com; yangkijung@kr.kpmg.com; sungchaekang@kr.kpmg.com; juneheeshin@kr.kpmg.com; djung4@kr.kpmg.com; jaenamhwang@kr.kpmg.com; dongjunshin@kr.kpmg.com; skim56@kr.kpmg.com; yosupgo@kr.kpmg.com; chaeneunglee@kr.kpmg.com; mbaek@kr.kpmg.com; yungicho@kr.kpmg.com; hsul@kr.kpmg.com; yseol@kr.kpmg.com; jinjang@kr.kpmg.com; jongseokyoun@kr.kpmg.com; cahn@kr.kpmg.com; yeontaekchoi@kr.kpmg.com; hkim108@kr.kpmg.com; mingyuhan@kr.kpmg.com; yhyun@kr.kpmg.com; siwookim@kr.kpmg.com; seungjaeoh@kr.kpmg.com; kwangsulee@kr.kpmg.com; joohunyoon@kr.kpmg.com; ikchankim@kr.kpmg.com; yoonahlee@kr.kpmg.com; hyeongcheollee@kr.kpmg.com; sanghoroh@kr.kpmg.com; wjeon@kr.kpmg.com; seongilkim@kr.kpmg.com; gibaeksong@kr.kpmg.com; hyunwootak@kr.kpmg.com; yhyun@kr.kpmg.com; hchung@kr.kpmg.com; clee60@kr.kpmg.com; ychoi@kr.kpmg.com; sungbaekim@kr.kpmg.com; jongsunam@kr.kpmg.com; hchung@kr.kpmg.com; joongkyukim@kr.kpmg.com; yaehyeonkim@kr.kpmg.com; konkukkang@kr.kpmg.com; jra@kr.kpmg.com; jjoung@kr.kpmg.com; yeasolju@kr.kpmg.com; ckim12@kr.kpmg.com; sungbaepark@kr.kpmg.com; yeontaekchoi@kr.kpmg.com; jjung32@kr.kpmg.com; dchi@kr.kpmg.com; hwasoocho@kr.kpmg.com; yeasolju@kr.kpmg.com; ykim47@kr.kpmg.com; hyunminjang@kr.kpmg.com; sangkilee@kr.kpmg.com; sehyunlee@kr.kpmg.com; ykim85@kr.kpmg.com; kyungsuklee@kr.kpmg.com; sanghoroh@kr.kpmg.com; jeongheehan@kr.kpmg.com; ychoi@kr.kpmg.com; sanghyunbyun@kr.kpmg.com; younginwon@kr.kpmg.com; sunseokcha@kr.kpmg.com; jra@kr.kpmg.com; jongsanglee@kr.kpmg.com; jchoi13@kr.kpmg.com; moonchulshin@kr.kpmg.com; sungbaepark@kr.kpmg.com; jaejoongkim@kr.kpmg.com; hocheolyang@kr.kpmg.com; chaeneunglee@kr.kpmg.com; ycha@kr.kpmg.com; seongilkim@kr.kpmg.com; gimyeonghwang@kr.kpmg.com; sanghyunhan@kr.kpmg.com; sungbaepark@kr.kpmg.com; jahn6@kr.kpmg.com; mkang8@kr.kpmg.com; hyunsukkim@kr.kpmg.com; hyundonghwang@kr.kpmg.com; changwonseo@kr.kpmg.com; gyeongokim@kr.kpmg.com; tkim@kr.kpmg.com; dohyunkim@kr.kpmg.com; jongsunam@kr.kpmg.com; taeseoblee@kr.kpmg.com; sangkeunlee@kr.kpmg.com; wjeon@kr.kpmg.com; inchanhwang@kr.kpmg.com; howonyoon@kr.kpmg.com; jroh@kr.kpmg.com; hsul@kr.kpmg.com; hlee42@kr.kpmg.com; hyegyeongryu@kr.kpmg.com; moonchulshin@kr.kpmg.com; kyunghopark@kr.kpmg.com; jinholee1@kr.kpmg.com; ikang@kr.kpmg.com; sanghoonpark@kr.kpmg.com; mingyulee@kr.kpmg.com; skim106@kr.kpmg.com; seungmikang@kr.kpmg.com; syeom@kr.kpmg.com; semokim@kr.kpmg.com; sanghyunhan@kr.kpmg.com; hakbeomlee@kr.kpmg.com; sorakim@kr.kpmg.com; yeehyunchoi@kr.kpmg.com; yeontaekchoi@kr.kpmg.com; jeongungcha@kr.kpmg.com; changilwon@kr.kpmg.com; hchung@kr.kpmg.com; junheehan@kr.kpmg.com; seunghoikoo@kr.kpmg.com; juhyunglee@kr.kpmg.com; jinmokkim@kr.kpmg.com; eunjeonghong@kr.kpmg.com; sangminnam@kr.kpmg.com; kyuhonglee1@kr.kpmg.com; suminpark@kr.kpmg.com; yanghoshin@kr.kpmg.com; sanghyunhan@kr.kpmg.com; yangkijung@kr.kpmg.com; jongroklee@kr.kpmg.com; hyunsukkim@kr.kpmg.com; hochullee@kr.kpmg.com; hkim51@kr.kpmg.com; sangminnam@kr.kpmg.com; yeonjungkim@kr.kpmg.com; sunguckkim@kr.kpmg.com; hkim51@kr.kpmg.com; sangminnam@kr.kpmg.com; sungbaekim@kr.kpmg.com; suminpark@kr.kpmg.com; myoungjaejeon@kr.kpmg.com; yongholee@kr.kpmg.com; siwookim@kr.kpmg.com; seungjaeoh@kr.kpmg.com; skim127@kr.kpmg.com; kyungsuklee@kr.kpmg.com; slee14@kr.kpmg.com; jungwookdo@kr.kpmg.com; jungsoopark@kr.kpmg.com; jinyoungson@kr.kpmg.com; yeonjoochoi@kr.kpmg.com; yseol@kr.kpmg.com; hongminpark@kr.kpmg.com; shinyoungkim@kr.kpmg.com; naehyeongkwon@kr.kpmg.com; kwanjongpark@kr.kpmg.com; hjo@kr.kpmg.com; changhyunan@kr.kpmg.com; jkim216@kr.kpmg.com; changgiljung@kr.kpmg.com; jungsoopark@kr.kpmg.com; sungwoonchoi@kr.kpmg.com; juhyunglee@kr.kpmg.com; sangilhan@kr.kpmg.com; sanghwapark@kr.kpmg.com; jungwookdo@kr.kpmg.com; ijo@kr.kpmg.com; juhyungkim@kr.kpmg.com; soh10@kr.kpmg.com; smin@kr.kpmg.com; seungmikang@kr.kpmg.com; yoorachoi@kr.kpmg.com; dongyoonlee@kr.kpmg.com; ikang@kr.kpmg.com; soyoungpark@kr.kpmg.com; mcho5@kr.kpmg.com; sangokpark@kr.kpmg.com; sukwangkim@kr.kpmg.com; mjang3@kr.kpmg.com; wjeon@kr.kpmg.com; yangkijung@kr.kpmg.com; eunseokkim@kr.kpmg.com; chaeneunglee@kr.kpmg.com; dongjunshin@kr.kpmg.com; skim56@kr.kpmg.com; sujungna@kr.kpmg.com; hyunhojeon@kr.kpmg.com; sbeom@kr.kpmg.com; khur@kr.kpmg.com; jaehoonheo@kr.kpmg.com; wonseol@kr.kpmg.com; euijinkim@kr.kpmg.com; byungyuljung@kr.kpmg.com; dchi@kr.kpmg.com; hwasoocho@kr.kpmg.com; jinseokyang@kr.kpmg.com; jeongeunshin@kr.kpmg.com; wjeon@kr.kpmg.com; ychoi@kr.kpmg.com; kyu3@kr.kpmg.com; yhyun@kr.kpmg.com; changgiljung@kr.kpmg.com; sungwookkim@kr.kpmg.com; jongsanglee@kr.kpmg.com; jaenamhwang@kr.kpmg.com; younginwon@kr.kpmg.com; jlee92@kr.kpmg.com; bohyunyoon@kr.kpmg.com; tkim@kr.kpmg.com; khwang@kr.kpmg.com; jiheonkang@kr.kpmg.com; sanghoonpark@kr.kpmg.com; khwang@kr.kpmg.com; skim125@kr.kpmg.com; gbak@kr.kpmg.com; jongsanglee@kr.kpmg.com; sanghyunbyun@kr.kpmg.com; younginwon@kr.kpmg.com; yongbeomlee@kr.kpmg.com; jeonggukang@kr.kpmg.com; jooyounglee@kr.kpmg.com; sungheeyoo@kr.kpmg.com; minkyungshin@kr.kpmg.com; ikang@kr.kpmg.com; jinseokchoi@kr.kpmg.com; junhyeoklee@kr.kpmg.com; daeryukjeong@kr.kpmg.com; tkim@kr.kpmg.com; sangokpark@kr.kpmg.com; sangseokseo@kr.kpmg.com; hoyoungshin@kr.kpmg.com; sanghoonpark@kr.kpmg.com; jungwookdo@kr.kpmg.com; hkim23@kr.kpmg.com; jihamchoi@kr.kpmg.com; jongsanglee@kr.kpmg.com; jeonggukang@kr.kpmg.com; kwanghyunyun@kr.kpmg.com; sungchaekang@kr.kpmg.com; jungsoolee@kr.kpmg.com; sunguckkim@kr.kpmg.com; sunghobu@kr.kpmg.com; sehongchoi@kr.kpmg.com; mbaek@kr.kpmg.com; spark20@kr.kpmg.com; sanghoroh@kr.kpmg.com; deokyeonglee@kr.kpmg.com; jeonghoonpark@kr.kpmg.com; seungheecho@kr.kpmg.com; kyungsuklee@kr.kpmg.com; slee14@kr.kpmg.com; hchung@kr.kpmg.com; yongholee@kr.kpmg.com; bkim13@kr.kpmg.com; yongwookkim@kr.kpmg.com; kwanjongpark@kr.kpmg.com; hjo@kr.kpmg.com; changhyunan@kr.kpmg.com; jbak@kr.kpmg.com; ijo@kr.kpmg.com; soonjaeyang@kr.kpmg.com; wooseokheo@kr.kpmg.com; jooyounglee@kr.kpmg.com; sangokpark@kr.kpmg.com; jongkeunpark@kr.kpmg.com; hyunhojeon@kr.kpmg.com; taeungjeon@kr.kpmg.com; hkim51@kr.kpmg.com; kwanjongpark@kr.kpmg.com; hakbeomlee@kr.kpmg.com; changwonseo@kr.kpmg.com; yeonjuchu@kr.kpmg.com; heeseokkang@kr.kpmg.com; jooyounglee@kr.kpmg.com; sungheeyoo@kr.kpmg.com; dlee89@kr.kpmg.com; jeewonlee@kr.kpmg.com; jaehoonheo@kr.kpmg.com; jinjang@kr.kpmg.com; jaehyunjeon@kr.kpmg.com; khwang@kr.kpmg.com; sukwangkim@kr.kpmg.com; hkim23@kr.kpmg.com; dongjoonchi@kr.kpmg.com; junsikuhm@kr.kpmg.com; yangkijung@kr.kpmg.com; jaewanlim@kr.kpmg.com; kyunghopark@kr.kpmg.com; dohyunkim@kr.kpmg.com; mingyusong@kr.kpmg.com; jkim258@kr.kpmg.com; hchung@kr.kpmg.com; yongholee@kr.kpmg.com; soonjaeyang@kr.kpmg.com; ihwang7@kr.kpmg.com; hyunminjang@kr.kpmg.com; kwanjongpark@kr.kpmg.com; jaehyoungan@kr.kpmg.com; wonjaekang@kr.kpmg.com; ikang@kr.kpmg.com; jaehoonheo@kr.kpmg.com; yoonahlee@kr.kpmg.com; junhyeoklee@kr.kpmg.com; hyucksoonchoi@kr.kpmg.com; hyunhojeon@kr.kpmg.com; yeonjungkim@kr.kpmg.com; kwanghyunyun@kr.kpmg.com; sangokpark@kr.kpmg.com; yeounchoi@kr.kpmg.com; suyeonkim@kr.kpmg.com; dchi@kr.kpmg.com; sangminnam@kr.kpmg.com; pjeong@kr.kpmg.com; dongjunshin@kr.kpmg.com; sukwangkim@kr.kpmg.com; jkim143@kr.kpmg.com; jhwang4@kr.kpmg.com; daejinkim@kr.kpmg.com; hochullee@kr.kpmg.com; sunguckkim@kr.kpmg.com; junhyunghong@kr.kpmg.com; smin@kr.kpmg.com; jaehoonheo@kr.kpmg.com; donggyulee@kr.kpmg.com; sangokpark@kr.kpmg.com; daejinkim@kr.kpmg.com; yulcheolpark@kr.kpmg.com; ylee67@kr.kpmg.com; jaenamhwang@kr.kpmg.com; kyunghopark@kr.kpmg.com; jlee123@kr.kpmg.com; sungchaekang@kr.kpmg.com; yongholee@kr.kpmg.com; jinyoungson@kr.kpmg.com; chulyoungkim@kr.kpmg.com; hwasoocho@kr.kpmg.com; jinseokyang@kr.kpmg.com; yeonjuchu@kr.kpmg.com; khwang@kr.kpmg.com; dohyunkim@kr.kpmg.com; mkim175@kr.kpmg.com; dkim240@kr.kpmg.com; sangkeunlee@kr.kpmg.com; hyunminjang@kr.kpmg.com; woohyunyi@kr.kpmg.com; changgiljung@kr.kpmg.com; dchi@kr.kpmg.com; inchanhwang@kr.kpmg.com; syoo7@kr.kpmg.com; hchung@kr.kpmg.com; yongholee@kr.kpmg.com; yaehyeonkim@kr.kpmg.com; konkukkang@kr.kpmg.com; chulyoungkim@kr.kpmg.com; kyungsuklee@kr.kpmg.com; slee14@kr.kpmg.com; hyunminjang@kr.kpmg.com; jungwookdo@kr.kpmg.com; minjujeong@kr.kpmg.com; kyunghopark@kr.kpmg.com; gleem@kr.kpmg.com; jeonghoonpark@kr.kpmg.com; jungkikim@kr.kpmg.com; moonchulshin@kr.kpmg.com; edo@kr.kpmg.com; seungohwoo@kr.kpmg.com; sangilhan@kr.kpmg.com; jlee79@kr.kpmg.com; sungwoonchoi@kr.kpmg.com; sangilhan@kr.kpmg.com; jlee79@kr.kpmg.com; bkim13@kr.kpmg.com; yongwookkim@kr.kpmg.com; jungsoolee@kr.kpmg.com; jjoung@kr.kpmg.com; jaeyeonleem@kr.kpmg.com; jlee177@kr.kpmg.com; cahn@kr.kpmg.com; yseol@kr.kpmg.com; yoorachoi@kr.kpmg.com; seungheecho@kr.kpmg.com; sanghoonpark@kr.kpmg.com; jlee92@kr.kpmg.com; hyim@kr.kpmg.com; jooyounglee@kr.kpmg.com; chaeneunglee@kr.kpmg.com; jongroklee@kr.kpmg.com; jungkikim@kr.kpmg.com; sanghyunkang@kr.kpmg.com; euijinkim@kr.kpmg.com; jooyounglee@kr.kpmg.com; seunghoikoo@kr.kpmg.com; jeonghoonlee@kr.kpmg.com; siwookim@kr.kpmg.com; ijo@kr.kpmg.com; gyeon@kr.kpmg.com; sungchaekang@kr.kpmg.com; seungmikang@kr.kpmg.com; woohyunyi@kr.kpmg.com; sukheehan@kr.kpmg.com; chaeneunglee@kr.kpmg.com; daejinkim@kr.kpmg.com; jaehyukjang@kr.kpmg.com; hcho12@kr.kpmg.com; seungmikang@kr.kpmg.com; moonchulshin@kr.kpmg.com; scho3@kr.kpmg.com; jroh@kr.kpmg.com; hsul@kr.kpmg.com; seongbeomlee@kr.kpmg.com; sungbaekim@kr.kpmg.com; hyundonghwang@kr.kpmg.com; giwoongbae@kr.kpmg.com; junsikuhm@kr.kpmg.com; taeungjeon@kr.kpmg.com; hkim51@kr.kpmg.com; ijo@kr.kpmg.com; tkim@kr.kpmg.com; jkim143@kr.kpmg.com; seungmikang@kr.kpmg.com; yeontaekchoi@kr.kpmg.com; ykang4@kr.kpmg.com; hakbeomlee@kr.kpmg.com; daejinkim@kr.kpmg.com; jaehyukjang@kr.kpmg.com; jungohyoon@kr.kpmg.com; jungkikim@kr.kpmg.com; yeehyunchoi@kr.kpmg.com; sangkilee@kr.kpmg.com; seungmikang@kr.kpmg.com; woohyunyi@kr.kpmg.com; yeonjungkim@kr.kpmg.com; heeseokkang@kr.kpmg.com; jchoi13@kr.kpmg.com; hyunminjang@kr.kpmg.com; kwanjongpark@kr.kpmg.com; jaehyoungan@kr.kpmg.com; wonjaekang@kr.kpmg.com; jaeyeonkim@kr.kpmg.com; jra@kr.kpmg.com; yulcheolpark@kr.kpmg.com; kwonjaelee@kr.kpmg.com; sukwangkim@kr.kpmg.com; yhyun@kr.kpmg.com; yaehyeonkim@kr.kpmg.com; sehongchoi@kr.kpmg.com; kyuhonglee1@kr.kpmg.com; mkim175@kr.kpmg.com; daejinkim@kr.kpmg.com; jjoung@kr.kpmg.com; giwoongbae@kr.kpmg.com; dongyoonlee@kr.kpmg.com; ikang@kr.kpmg.com; taehyunglee@kr.kpmg.com; doheunkim@kr.kpmg.com; heeseokkang@kr.kpmg.com; yeounchoi@kr.kpmg.com; jaehyukjang@kr.kpmg.com; dokyunglee@kr.kpmg.com; hakbeomlee@kr.kpmg.com; jeonghwancha@kr.kpmg.com; sungkyujung@kr.kpmg.com; jinhyeokwoo@kr.kpmg.com; kyunghopark@kr.kpmg.com; yeounchoi@kr.kpmg.com; jlee92@kr.kpmg.com; gyucheoloh@kr.kpmg.com; jaeyeonkim@kr.kpmg.com; wjeon@kr.kpmg.com; sungheeyoo@kr.kpmg.com; hyunwootak@kr.kpmg.com; ycha@kr.kpmg.com; heeseokkang@kr.kpmg.com; jlee123@kr.kpmg.com; changgiljung@kr.kpmg.com; yongholee@kr.kpmg.com; jaehyoungan@kr.kpmg.com; wonjaekang@kr.kpmg.com; dongjunshin@kr.kpmg.com; hochullee@kr.kpmg.com; sunguckkim@kr.kpmg.com; tkim50@kr.kpmg.com; jjoung@kr.kpmg.com; sbeom@kr.kpmg.com; hyoungtakhan@kr.kpmg.com; ychoi@kr.kpmg.com; dchi@kr.kpmg.com; yeongminlee@kr.kpmg.com; spark72@kr.kpmg.com; junsikuhm@kr.kpmg.com; yeounchoi@kr.kpmg.com; suyeonkim@kr.kpmg.com; sanghyunkang@kr.kpmg.com; jeewonlee@kr.kpmg.com; jboo@kr.kpmg.com; ychoi@kr.kpmg.com; ycha@kr.kpmg.com; jlee92@kr.kpmg.com; kyungsunkwon@kr.kpmg.com; daejinkim@kr.kpmg.com; sungchaekang@kr.kpmg.com; spark20@kr.kpmg.com; yeehyunchoi@kr.kpmg.com; yeontaekchoi@kr.kpmg.com; ykang4@kr.kpmg.com; smin@kr.kpmg.com; yeehyunchoi@kr.kpmg.com; jaeyoungpark@kr.kpmg.com; joohunyoon@kr.kpmg.com; daejinkim@kr.kpmg.com; jlee92@kr.kpmg.com; jungohyoon@kr.kpmg.com; yangkijung@kr.kpmg.com; hochullee@kr.kpmg.com; sseo@kr.kpmg.com; dohyunkim@kr.kpmg.com; daejinkim@kr.kpmg.com; suyeonkim@kr.kpmg.com; chulyoungkim@kr.kpmg.com; sangminnam@kr.kpmg.com; eunseokkim@kr.kpmg.com; khwang@kr.kpmg.com; jungwookdo@kr.kpmg.com; jkim143@kr.kpmg.com; jihoonchoo@kr.kpmg.com; seunghoikoo@kr.kpmg.com; seungmikang@kr.kpmg.com; woohyunyi@kr.kpmg.com; sukheehan@kr.kpmg.com; jongwoolee@kr.kpmg.com; joongkyukim@kr.kpmg.com; yaehyeonkim@kr.kpmg.com; cbae1@kr.kpmg.com; hyunsukkim@kr.kpmg.com; seungmikang@kr.kpmg.com; jaeyoungpark@kr.kpmg.com; hyeongcheollee@kr.kpmg.com; jongsanglee@kr.kpmg.com; jungwoohan@kr.kpmg.com; yno@kr.kpmg.com; dohyunkim@kr.kpmg.com; jra@kr.kpmg.com; younakim@kr.kpmg.com; jungsoopark@kr.kpmg.com; siwookim@kr.kpmg.com; sanghwapark@kr.kpmg.com; youngjoojin@kr.kpmg.com; kiwoongkim@kr.kpmg.com; ikchankim@kr.kpmg.com; seunghoikoo@kr.kpmg.com; scho3@kr.kpmg.com; sehongchoi@kr.kpmg.com; kyuhonglee1@kr.kpmg.com; jongsunam@kr.kpmg.com; jeonghwancha@kr.kpmg.com; dongyoonlee@kr.kpmg.com; hyejujang@kr.kpmg.com; yeonjungkim@kr.kpmg.com; hongminpark@kr.kpmg.com; edo@kr.kpmg.com; seungheecho@kr.kpmg.com; ycha@kr.kpmg.com; mingyulee@kr.kpmg.com; dasanyoun@kr.kpmg.com; dongyoonlee@kr.kpmg.com; hyunminjang@kr.kpmg.com; hyeonggilwi@kr.kpmg.com; cahn@kr.kpmg.com; sehongchoi@kr.kpmg.com; sorakim@kr.kpmg.com; smin@kr.kpmg.com; cahn@kr.kpmg.com; seoyoungnam@kr.kpmg.com; joonggimin@kr.kpmg.com; daejinkim@kr.kpmg.com; joongkyukim@kr.kpmg.com; jiheonkang@kr.kpmg.com; chulyoungkim@kr.kpmg.com; hwasoocho@kr.kpmg.com; jinseokyang@kr.kpmg.com; hyunjaeim@kr.kpmg.com; hyundonghwang@kr.kpmg.com; heeseokkang@kr.kpmg.com; dlee34@kr.kpmg.com; jaehoonheo@kr.kpmg.com; tkim@kr.kpmg.com; seunghyeonpark@kr.kpmg.com; jungkikim@kr.kpmg.com; hyundonghwang@kr.kpmg.com; jaeyeonleem@kr.kpmg.com; jkim508@kr.kpmg.com; sangilhan@kr.kpmg.com; kwanjongpark@kr.kpmg.com; jinyoungson@kr.kpmg.com; yeonjoochoi@kr.kpmg.com; sbeom@kr.kpmg.com; hchung@kr.kpmg.com; junheehan@kr.kpmg.com; jungsoopark@kr.kpmg.com; sanghoonpark@kr.kpmg.com; sungheeyoo@kr.kpmg.com; dkim77@kr.kpmg.com; jungwoohan@kr.kpmg.com; khwang@kr.kpmg.com; jiheonkang@kr.kpmg.com; sbeom@kr.kpmg.com; wjeon@kr.kpmg.com; skim66@kr.kpmg.com; kyungsuklee@kr.kpmg.com; sanghoroh@kr.kpmg.com; sorakim@kr.kpmg.com; yangkijung@kr.kpmg.com; smin@kr.kpmg.com; hlee42@kr.kpmg.com; jeonghwancha@kr.kpmg.com; yoongeunoh@kr.kpmg.com; yungicho@kr.kpmg.com; seungmikang@kr.kpmg.com; sukwangkim@kr.kpmg.com; clee60@kr.kpmg.com; sangilhan@kr.kpmg.com; minjujeong@kr.kpmg.com; jooyounglee@kr.kpmg.com; seunghoikoo@kr.kpmg.com; jahn6@kr.kpmg.com; naehyeongkwon@kr.kpmg.com; hyunminjang@kr.kpmg.com; seunghoikoo@kr.kpmg.com; jeonghoonlee@kr.kpmg.com; wonseol@kr.kpmg.com; jeonghwancha@kr.kpmg.com; seoyoungnam@kr.kpmg.com; mincheolyun@kr.kpmg.com; hyunhojeon@kr.kpmg.com; kyuhonglee1@kr.kpmg.com; mkim175@kr.kpmg.com; joongkyukim@kr.kpmg.com; hjo@kr.kpmg.com; clee60@kr.kpmg.com; jkim181@kr.kpmg.com; jungsoolee@kr.kpmg.com; jjoung@kr.kpmg.com; changwonseo@kr.kpmg.com; jlee177@kr.kpmg.com; jongwoolee@kr.kpmg.com; seunghyeonpark@kr.kpmg.com; yoongeunoh@kr.kpmg.com; yungicho@kr.kpmg.com; hochullee@kr.kpmg.com; mkim175@kr.kpmg.com; tkim@kr.kpmg.com; mjang3@kr.kpmg.com; seungheecho@kr.kpmg.com; tkim@kr.kpmg.com; jkim143@kr.kpmg.com; youngmokoo@kr.kpmg.com; yeehyunchoi@kr.kpmg.com; yeontaekchoi@kr.kpmg.com; sungkyujung@kr.kpmg.com; jinhyeokwoo@kr.kpmg.com
B3: seungmikang@kr.kpmg.com, jeewonlee@kr.kpmg.com, jinboshim@kr.kpmg.com, jlee79@kr.kpmg.com, semokim@kr.kpmg.com, jjung9@kr.kpmg.com | S3: seungmikang@kr.kpmg.com, jeewonlee@kr.kpmg.com, jinboshim@kr.kpmg.com, jlee79@kr.kpmg.com, semokim@kr.kpmg.com, jjung9@kr.kpmg.com | T3: =SUBSTITUTE(S3,", ","; ") -> seungmikang@kr.kpmg.com; jeewonlee@kr.kpmg.com; jinboshim@kr.kpmg.com; jlee79@kr.kpmg.com; semokim@kr.kpmg.com; jjung9@kr.kpmg.com
B4: jungkikim@kr.kpmg.com, yeehyunchoi@kr.kpmg.com, euijinkim@kr.kpmg.com | S4: jungkikim@kr.kpmg.com, yeehyunchoi@kr.kpmg.com, euijinkim@kr.kpmg.com | T4: =SUBSTITUTE(S4,", ","; ") -> jungkikim@kr.kpmg.com; yeehyunchoi@kr.kpmg.com; euijinkim@kr.kpmg.com
B5: yangkijung@kr.kpmg.com, sungchaekang@kr.kpmg.com, juneheeshin@kr.kpmg.com, djung4@kr.kpmg.com | S5: yangkijung@kr.kpmg.com, sungchaekang@kr.kpmg.com, juneheeshin@kr.kpmg.com, djung4@kr.kpmg.com | T5: =SUBSTITUTE(S5,", ","; ") -> yangkijung@kr.kpmg.com; sungchaekang@kr.kpmg.com; juneheeshin@kr.kpmg.com; djung4@kr.kpmg.com
B6: jaenamhwang@kr.kpmg.com, dongjunshin@kr.kpmg.com, skim56@kr.kpmg.com, yosupgo@kr.kpmg.com | S6: jaenamhwang@kr.kpmg.com, dongjunshin@kr.kpmg.com, skim56@kr.kpmg.com, yosupgo@kr.kpmg.com | T6: =SUBSTITUTE(S6,", ","; ") -> jaenamhwang@kr.kpmg.com; dongjunshin@kr.kpmg.com; skim56@kr.kpmg.com; yosupgo@kr.kpmg.com
B7: chaeneunglee@kr.kpmg.com, mbaek@kr.kpmg.com, yungicho@kr.kpmg.com | S7: chaeneunglee@kr.kpmg.com, mbaek@kr.kpmg.com, yungicho@kr.kpmg.com | T7: =SUBSTITUTE(S7,", ","; ") -> chaeneunglee@kr.kpmg.com; mbaek@kr.kpmg.com; yungicho@kr.kpmg.com
B8: hsul@kr.kpmg.com, yseol@kr.kpmg.com, jinjang@kr.kpmg.com, jongseokyoun@kr.kpmg.com | S8: hsul@kr.kpmg.com, yseol@kr.kpmg.com, jinjang@kr.kpmg.com, jongseokyoun@kr.kpmg.com | T8: =SUBSTITUTE(S8,", ","; ") -> hsul@kr.kpmg.com; yseol@kr.kpmg.com; jinjang@kr.kpmg.com; jongseokyoun@kr.kpmg.com
B9: cahn@kr.kpmg.com, yeontaekchoi@kr.kpmg.com, hkim108@kr.kpmg.com, mingyuhan@kr.kpmg.com | S9: cahn@kr.kpmg.com, yeontaekchoi@kr.kpmg.com, hkim108@kr.kpmg.com, mingyuhan@kr.kpmg.com | T9: =SUBSTITUTE(S9,", ","; ") -> cahn@kr.kpmg.com; yeontaekchoi@kr.kpmg.com; hkim108@kr.kpmg.com; mingyuhan@kr.kpmg.com
B10: yhyun@kr.kpmg.com, siwookim@kr.kpmg.com, seungjaeoh@kr.kpmg.com, kwangsulee@kr.kpmg.com | S10: yhyun@kr.kpmg.com, siwookim@kr.kpmg.com, seungjaeoh@kr.kpmg.com, kwangsulee@kr.kpmg.com | T10: =SUBSTITUTE(S10,", ","; ") -> yhyun@kr.kpmg.com; siwookim@kr.kpmg.com; seungjaeoh@kr.kpmg.com; kwangsulee@kr.kpmg.com
B11: joohunyoon@kr.kpmg.com, ikchankim@kr.kpmg.com, yoonahlee@kr.kpmg.com, hyeongcheollee@kr.kpmg.com | S11: joohunyoon@kr.kpmg.com, ikchankim@kr.kpmg.com, yoonahlee@kr.kpmg.com, hyeongcheollee@kr.kpmg.com | T11: =SUBSTITUTE(S11,", ","; ") -> joohunyoon@kr.kpmg.com; ikchankim@kr.kpmg.com; yoonahlee@kr.kpmg.com; hyeongcheollee@kr.kpmg.com
